Workbook

Sheet PORTAFOGLIO A 3
A1: =_xll.Thomson.Reuters.AFOSpreadsheetFormulas.DSGRID("@AAPL,@AMZN,@FB"," ","-5Y","","D","RowHeader=true;ColHeader=true;Heading=true;LatestFirstValue=true;DispSeriesDescription=false;YearlyTSFormat=false;QuarterlyTSFormat=false","") -> #NAME? | B1: 42283
A2: End | B2: 44110
A3: Frequency | B3: D | F3: Return
A4: Name | B4: APPLE | C4: AMAZON.COM | D4: FACEBOOK CLASS A | F4: APPLE | G4: AMAZON.COM | H4: FACEBOOK CLASS A | K4: APPLE | L4: AMAZON.COM | M4: FACEBOOK CLASS A | P4: Inverse V | Q4: {=MINVERSE(K7:M9)} -> 4933.5953 | R4: -1830.6199 | S4: -1521.5813
A5: 44110 | B5: 113.16 | C5: 3099.96 | D5: 258.6599 | F5: =LN(B5/B6) -> -0.029088527 | G5: =LN(C5/C6) -> -0.03151157 | H5: =LN(D5/D6) -> -0.022893749 | J5: Mean | K5: =AVERAGE(F5:F1303) -> 0.0010798907 | L5: =AVERAGE(G5:G1303) -> 0.0013489245 | M5: =AVERAGE(H5:H1303) -> 0.00078912042 | Q5: -1830.6199 | R5: 5350.6223 | S5: -2111.6995
A6: 44109 | B6: 116.5 | C6: 3199.2 | D6: 264.6499 | F6: =LN(B6/B7) -> 0.030326479 | G6: =LN(C6/C7) -> 0.023466495 | H6: =LN(D6/D7) -> 0.01795737 | Q6: -1521.5813 | R6: -2111.6995 | S6: 4460.4394
A7: 44106 | B7: 113.02 | C7: 3125 | D7: 259.9399 | F7: =LN(B7/B8) -> -0.032812656 | G7: =LN(C7/C8) -> -0.030338304 | H7: =LN(D7/D8) -> -0.025411104 | J7: V=VarCov Matrix | K7: =_xlfn.COVARIANCE.P($F$5:$F$1303,F5:F1303) -> 0.00034259856 | L7: =_xlfn.COVARIANCE.P($F$5:$F$1303,G5:G1303) -> 0.00020087003 | M7: =_xlfn.COVARIANCE.P($F$5:$F$1303,H5:H1303) -> 0.00021196761 | N7: APPLE
A8: 44105 | B8: 116.79 | C8: 3221.26 | D8: 266.6299 | F8: =LN(B8/B9) -> 0.0084265331 | G8: =LN(C8/C9) -> 0.02277339 | H8: =LN(D8/D9) -> 0.017899185 | K8: =_xlfn.COVARIANCE.P($F$5:$F$1303,G5:G1303) -> 0.00020087003 | L8: =_xlfn.COVARIANCE.P($G$5:$G$1303,G5:G1303) -> 0.00034761112 | M8: =_xlfn.COVARIANCE.P($G$5:$G$1303,H5:H1303) -> 0.00023309145 | N8: AMAZON.COM
A9: 44104 | B9: 115.81 | C9: 3148.73 | D9: 261.8999 | F9: =LN(B9/B10) -> 0.014963307 | G9: =LN(C9/C10) -> 0.0012234633 | H9: =LN(D9/D10) -> 0.00041971404 | K9: =_xlfn.COVARIANCE.P($F$5:$F$1303,H5:H1303) -> 0.00021196761 | L9: =_xlfn.COVARIANCE.P($G$5:$G$1303,H5:H1303) -> 0.00023309145 | M9: =_xlfn.COVARIANCE.P(H5:H1303,H5:H1303) -> 0.00040685343 | N9: FACEBOOK CLASS A | P9: Check | Q9: {=MMULT(K7:M9,Q4:S6)} -> 1 | R9: 0 | S9: 0
A10: 44103 | B10: 114.09 | C10: 3144.88 | D10: 261.79 | F10: =LN(B10/B11) -> -0.0075966312 | G10: =LN(C10/C11) -> -0.0092326414 | H10: =LN(D10/D11) -> 0.019166816 | Q10: 1.110223e-16 | R10: 1 | S10: 0
A11: 44102 | B11: 114.96 | C11: 3174.05 | D11: 256.8201 | F11: =LN(B11/B12) -> 0.02358849 | G11: =LN(C11/C12) -> 0.025178466 | H11: =LN(D11/D12) -> 0.0078184262 | Q11: -2.220446e-16 | R11: -1.110223e-16 | S11: 1
A12: 44099 | B12: 112.28 | C12: 3095.13 | D12: 254.82 | F12: =LN(B12/B13) -> 0.036829559 | G12: =LN(C12/C13) -> 0.024642616 | H12: =LN(D12/D13) -> 0.020978265
A13: 44098 | B13: 108.22 | C13: 3019.79 | D13: 249.53 | F13: =LN(B13/B14) -> 0.010216491 | G13: =LN(C13/C14) -> 0.0066216716 | H13: =LN(D13/D14) -> 0.0020459339
A14: 44097 | B14: 107.12 | C14: 2999.86 | D14: 249.02 | F14: =LN(B14/B15) -> -0.042851301 | G14: =LN(C14/C15) -> -0.042144648 | H14: =LN(D14/D15) -> -0.022749458 | P14: Mean | Q14: =K5 -> 0.0010798907
A15: 44096 | B15: 111.81 | C15: 3128.99 | D15: 254.75 | F15: =LN(B15/B16) -> 0.015593628 | G15: =LN(C15/C16) -> 0.055362229 | H15: =LN(D15/D16) -> 0.02624927 | Q15: =L5 -> 0.0013489245
A16: 44095 | B16: 110.08 | C16: 2960.47 | D16: 248.15 | F16: =LN(B16/B17) -> 0.029874986 | G16: =LN(C16/C17) -> 0.001879846 | H16: =LN(D16/D17) -> -0.017496652 | Q16: =M5 -> 0.00078912042
A17: 44092 | B17: 106.84 | C17: 2954.91 | D17: 252.53 | F17: =LN(B17/B18) -> -0.03223412 | G17: =LN(C17/C18) -> -0.018049869 | H17: =LN(D17/D18) -> -0.00902736 | J17: Curtosi | K17: =KURT(F5:F1303) -> 8.0948731 | L17: =KURT(G5:G1303) -> 4.8676563 | M17: =KURT(H5:H1303) -> 16.34058
A18: 44091 | B18: 110.34 | C18: 3008.73 | D18: 254.82 | F18: =LN(B18/B19) -> -0.016092405 | G18: =LN(C18/C19) -> -0.022794461 | H18: =LN(D18/D19) -> -0.033571853 | P18: Ones | Q18: 1 | S18: Ones | T18: 1 | U18: 1 | V18: 1
A19: 44090 | B19: 112.13 | C19: 3078.1 | D19: 263.52 | F19: =LN(B19/B20) -> -0.029957878 | G19: =LN(C19/C20) -> -0.02503407 | H19: =LN(D19/D20) -> -0.03321536 | Q19: 1
A20: 44089 | B20: 115.54 | C20: 3156.13 | D20: 272.4199 | F20: =LN(B20/B21) -> 0.0016024603 | G20: =LN(C20/C21) -> 0.016986876 | H20: =LN(D20/D21) -> 0.023284942 | Q20: 1
A21: 44088 | B21: 115.355 | C21: 3102.97 | D21: 266.1499 | F21: =LN(B21/B22) -> 0.029515459 | G21: =LN(C21/C22) -> -0.0042610115 | H21: =LN(D21/D22) -> -0.0017276076
A22: 44085 | B22: 112 | C22: 3116.22 | D22: 266.6101 | F22: =LN(B22/B23) -> -0.013215856 | G22: =LN(C22/C23) -> -0.018721549 | H22: =LN(D22/D23) -> -0.0055358265 | K22: Portafoglio a varianza minima(Frontiera)
A23: 44084 | B23: 113.49 | C23: 3175.11 | D23: 268.0901 | F23: =LN(B23/B24) -> -0.033190517 | G23: =LN(C23/C24) -> -0.029022541 | H23: =LN(D23/D24) -> -0.020782568 | M23: A=ones'*invV*mean; | P23: A | Q23: {=MMULT(MMULT(T18:V18,Q4:S6),Q14:Q16)} -> 4.2601547
A24: 44083 | B24: 117.32 | C24: 3268.61 | D24: 273.72 | F24: =LN(B24/B25) -> 0.039111616 | G24: =LN(C24/C25) -> 0.03701316 | H24: =LN(D24/D25) -> 0.0093970023 | M24: B=mean'*invV*mean; | P24: B | Q24: {=MMULT(MMULT(K5:M5,Q4:S6),Q14:Q16)} -> 0.0058446997
A25: 44082 | B25: 112.82 | C25: 3149.84 | D25: 271.1599 | F25: =LN(B25/B26) -> -0.069666284 | G25: =LN(C25/C26) -> -0.044939177 | H25: =LN(D25/D26) -> -0.041783695 | M25: C=ones'*invV*ones; | P25: C | Q25: {=MMULT(MMULT(T18:V18,Q4:S6),Q18:Q20)} -> 3816.8555
A26: 44078 | B26: 120.96 | C26: 3294.62 | D26: 282.73 | F26: =LN(B26/B27) -> 0.00066159447 | G26: =LN(C26/C27) -> -0.022028261 | H26: =LN(D26/D27) -> -0.029243518 | M26: D=B*C-A^2; | P26: D | Q26: =Q24*Q25-Q23*Q23 -> 4.1594563
A27: 44077 | B27: 120.88 | C27: 3368 | D27: 291.1201 | F27: =LN(B27/B28) -> -0.083447788 | G27: =LN(C27/C28) -> -0.047389455 | H27: =LN(D27/D28) -> -0.038345381 | M27: g=(B*(invV*ones)-A*(invV*mean))/D; | P27: g | Q27: {=(Q24*(MMULT(Q4:S6,Q18:Q20))-Q23*(MMULT(Q4:S6,Q14:Q16)))/Q26} -> 0.52431508
A28: 44076 | B28: 131.4 | C28: 3531.45 | D28: 302.5 | F28: =LN(B28/B29) -> -0.020936076 | G28: =LN(C28/C29) -> 0.0091970432 | H28: =LN(D28/D29) -> 0.023615845 | Q28: -1.6819735
A29: 44075 | B29: 134.18 | C29: 3499.12 | D29: 295.4399 | F29: =LN(B29/B30) -> 0.039059748 | G29: =LN(C29/C30) -> 0.013859055 | H29: =LN(D29/D30) -> 0.0076104621 | Q29: 2.1576585 | S29: w=@(R) g+h*R;
A30: 44074 | B30: 129.04 | C30: 3450.96 | D30: 293.2 | F30: =LN(B30/B31) -> 0.033349884 | G30: =LN(C30/C31) -> 0.01434775 | H30: =LN(D30/D31) -> -0.001567325 | M30: h=(-A*(invV*ones)+C*(invV*mean))/D; | P30: h | Q30: {=(-Q23*(MMULT(Q4:S6,Q18:Q20))+Q25*(MMULT(Q4:S6,Q14:Q16)))/Q26} -> -98.550607
A31: 44071 | B31: 124.8075 | C31: 3401.8 | D31: 293.6599 | F31: =LN(B31/B32) -> -0.0016211838 | G31: =LN(C31/C32) -> 0.00052927168 | H31: =LN(D31/D32) -> 0.0014991145 | Q31: 1837.5278
A32: 44070 | B32: 125.01 | C32: 3400 | D32: 293.22 | F32: =LN(B32/B33) -> -0.012026424 | G32: =LN(C32/C33) -> -0.012233686 | H32: =LN(D32/D33) -> -0.035808095 | Q32: -1738.9772
A33: 44069 | B33: 126.5225 | C33: 3441.85 | D33: 303.9099 | F33: =LN(B33/B34) -> 0.013507402 | G33: =LN(C33/C34) -> 0.028097082 | H33: =LN(D33/D34) -> 0.079017025
A34: 44068 | B34: 124.825 | C34: 3346.49 | D34: 280.8201 | F34: =LN(B34/B35) -> -0.0082375582 | G34: =LN(C34/C35) -> 0.011731512 | H34: =LN(D34/D35) -> 0.034157719 | M34: Exp Return | N34: Variance
A35: 44067 | B35: 125.8575 | C35: 3307.46 | D35: 271.3899 | F35: =LN(B35/B36) -> 0.011889321 | G35: =LN(C35/C36) -> 0.0068991108 | H35: =LN(D35/D36) -> 0.016270421 | M35: R | N35: (C*R.^2-2*A*R+B)/D
A36: 44064 | B36: 124.37 | C36: 3284.72 | D36: 267.01 | F36: =LN(B36/B37) -> 0.050248572 | G36: =LN(C36/C37) -> -0.0038437686 | H36: =LN(D36/D37) -> -0.0074624427 | M36: 0.999 | N36: =($Q$25*M36^2-2*$Q$23*M36+$Q$24)/$Q$26 -> 913.75397
A37: 44063 | B37: 118.275 | C37: 3297.37 | D37: 269.01 | F37: =LN(B37/B38) -> 0.021946967 | G37: =LN(C37/C38) -> 0.011250757 | H37: =LN(D37/D38) -> 0.024154292 | M37: 1 | N37: =($Q$25*M37^2-2*$Q$23*M37+$Q$24)/$Q$26 -> 915.58628
A38: 44062 | B38: 115.7075 | C38: 3260.48 | D38: 262.5901 | F38: =LN(B38/B39) -> 0.0012539458 | G38: =LN(C38/C39) -> -0.015825749 | H38: =LN(D38/D39) -> 0.00095250766 | M38: 1.001 | N38: =($Q$25*M38^2-2*$Q$23*M38+$Q$24)/$Q$26 -> 917.42041
A39: 44061 | B39: 115.5625 | C39: 3312.49 | D39: 262.3401 | F39: =LN(B39/B40) -> 0.008298262 | G39: =LN(C39/C40) -> 0.040061401 | H39: =LN(D39/D40) -> 0.0045088902
A40: 44060 | B40: 114.6075 | C40: 3182.41 | D40: 261.1599 | F40: =LN(B40/B41) -> -0.0026142097 | G40: =LN(C40/C41) -> 0.010865088 | H40: =LN(D40/D41) -> -0.00030666162
...

Sheet PORTAFOGLIO A
A1: Amazon e facebook
C4: Media | F4: Matrice V | K4: Matrice V inversa | N4: Media' | O4: =D5 -> 0.0013489245 | P4: =D6 -> 0.00078912042
C5: Amazon | D5: ='PORTAFOGLIO A 3'!L5 -> 0.0013489245 | F5: {='PORTAFOGLIO A 3'!L8:M9} -> 0.00034761112 | G5: 0.00023309145 | K5: {=MINVERSE(F5:G6)} -> 4671.3672 | L5: -2676.2851 | R5: p | S5: =G5/((F5^0.5)*(G6^0.5)) -> 0.61981279
C6: Facebook | D6: ='PORTAFOGLIO A 3'!M5 -> 0.00078912042 | F6: 0.00023309145 | G6: 0.00040685343 | K6: -2676.2851 | L6: 3991.165
C9: Ones | D9: 1 | F9: Ones' | G9: 1 | H9: 1
D10: 1
B13: Portafoglio a varianza minima(Frontiera) | C13: A=ones'*invV*mean; | F13: A | G13: {=MMULT(MMULT(G9:H9,K5:L6),D5:D6)} -> 3.7288138
C14: B=mean'*invV*mean; | F14: B | G14: {=MMULT(MMULT(O4:P4,K5:L6),D5:D6)} -> 0.0052877322
C15: C=ones'*invV*ones; | F15: C | G15: {=MMULT(MMULT(G9:H9,K5:L6),D9:D10)} -> 3309.962
C16: D=B*C-A^2; | F16: D | G16: =G14*G15-G13*G13 -> 3.5981408
C17: g=(B*(invV*ones)-A*(invV*mean))/D; | F17: g | G17: {=(G14*(MMULT(K5:L6,D9:D10))-G13*(MMULT(K5:L6,D5:D6)))/G16} -> -1.4096368
G18: 2.4096368
I19: w=@(R) g+h*R;
C20: h=(-A*(invV*ones)+C*(invV*mean))/D; | F20: h | G20: {=(-G13*(MMULT(K5:L6,D9:D10))+G15*(MMULT(K5:L6,D5:D6)))/G16} -> 1786.3392
G21: -1786.3392
C24: Exp Return | D24: Variance
C25: R | D25: (C*R.^2-2*A*R+B)/D
C26: 0.999 | D26: =($G$15*C26*C26-2*$G$13*C26+$G$14)/$G$16 -> 916.00099
C27: 1 | D27: =($G$15*C27*C27-2*$G$13*C27+$G$14)/$G$16 -> 917.83782
C28: 1.001 | D28: =($G$15*C28*C28-2*$G$13*C28+$G$14)/$G$16 -> 919.67648
B31: Portafoglio a varianza minima globale | C31: E[rp]=A/C | D31: =G13/G15 -> 0.0011265428 | L31: =(1+D31)^365 -> 1.50826
C33: wMVP=(invV*ones)/C | D33: {=MMULT(_xlfn.ANCHORARRAY(K5),D9:D10)/G15} -> 0.60275076
D34: 0.39724924

Sheet PORTAFOGLIO B
A1: Facebook e apple
C4: Media | F4: Matrice V | K4: Matrice V inversa | N4: Media' | O4: =D5 -> 0.00078912042 | P4: =D6 -> 0.0010798907
C5: Facebook | D5: ='PORTAFOGLIO A 3'!M5 -> 0.00078912042 | F5: ='PORTAFOGLIO A 3'!M9 -> 0.00040685343 | G5: ='PORTAFOGLIO A 3'!K9 -> 0.00021196761 | K5: {=MINVERSE(F5:G6)} -> 3627.027 | L5: -2244.0616
C6: Apple | D6: ='PORTAFOGLIO A 3'!K5 -> 0.0010798907 | F6: ='PORTAFOGLIO A 3'!M7 -> 0.00021196761 | G6: ='PORTAFOGLIO A 3'!K7 -> 0.00034259856 | K6: -2244.0616 | L6: 4307.2813
C9: Ones | D9: 1 | F9: Ones' | G9: 1 | H9: 1
D10: 1
B13: Portafoglio a varianza minima(Frontiera) | C13: A=ones'*invV*mean; | F13: A | G13: {=MMULT(MMULT(G9:H9,K5:L6),D5:D6)} -> 3.3193781
C14: B=mean'*invV*mean; | F14: B | G14: {=MMULT(MMULT(O4:P4,K5:L6),D5:D6)} -> 0.0034569697
C15: C=ones'*invV*ones; | F15: C | G15: {=MMULT(MMULT(G9:H9,K5:L6),D9:D10)} -> 3446.1852
C16: D=B*C-A^2; | F16: D | G16: =G14*G15-G13*G13 -> 0.89508698
C17: g=(B*(invV*ones)-A*(invV*mean))/D; | F17: g | G17: {=(G14*(MMULT(K5:L6,D9:D10))-G13*(MMULT(K5:L6,D5:D6)))/G16} -> 3.7138966
G18: -2.7138966
I19: w=@(R) g+h*R;
C20: h=(-A*(invV*ones)+C*(invV*mean))/D; | F20: h | G20: {=(-G13*(MMULT(K5:L6,D9:D10))+G15*(MMULT(K5:L6,D5:D6)))/G16} -> -3439.1412
G21: 3439.1412
C24: Exp Return | D24: Variance
C25: R | D25: (C*R.^2-2*A*R+B)/D
C26: 0.999 | D26: =($G$15*C26*C26-2*$G$13*C26+$G$14)/$G$16 -> 3835.0101
C27: 1 | D27: =($G$15*C27*C27-2*$G$13*C27+$G$14)/$G$16 -> 3842.6991
C28: 1.001 | D28: =($G$15*C28*C28-2*$G$13*C28+$G$14)/$G$16 -> 3850.3957
B31: Portafoglio a varianza minima globale | C31: E[rp]=A/C | D31: =G13/G15 -> 0.00096320363 | L31: =(1+D31)^365 -> 1.4210558
C33: wMVP=(invV*ones)/C | D33: {=MMULT(_xlfn.ANCHORARRAY(K5),D9:D10)/G15} -> 0.40130328
D34: 0.59869672

Sheet QUADRATICA
E2: MEDIA rendimento annua | G2: VARIANZA | M2: e-rf
B3: Normale multivariata X | D3: APPLE | E3: {=(1+'PORTAFOGLIO A 3'!Q14:Q16)^365} -> 1.4828226 | G3: {='PORTAFOGLIO A 3'!K7:M9} -> 0.00034259856 | H3: 0.00020087003 | I3: 0.00021196761 | K3: 1 | M3: =E3-$D$8 -> 0.47282259
D4: AMAZON | E4: 1.6356261 | G4: 0.00020087003 | H4: 0.00034761112 | I4: 0.00023309145 | K4: 1 | M4: =E4-$D$8 -> 0.6256261
D5: FACEBOOK | E5: 1.3336444 | G5: 0.00021196761 | H5: 0.00023309145 | I5: 0.00040685343 | K5: 1 | M5: =E5-$D$8 -> 0.32364443
B8: Rendimento titolo privo di rischio | D8: 1.01 | N8: Portafoglio tangente(wE) | O8: {=MMULT(MINVERSE(_xlfn.ANCHORARRAY(G3)),M3:M5)/(MMULT(MMULT(TRANSPOSE(K3:K5),MINVERSE(_xlfn.ANCHORARRAY(G3))),M3:M5))} -> 0.36645515
N9: invV*(e-rf*ones)/(onesTrasp*invV*(e-rf*ones)) | O9: 0.94832338
B10: b | D10: 0.001 | O10: -0.31477853
B12: Funzione utilità | D12: x+(b/2)*(x^2)
N13: E[rE]=wETrasposto*e | O13: {=MMULT(TRANSPOSE(_xlfn.ANCHORARRAY(O8)),_xlfn.ANCHORARRAY(E3))} -> 1.6746878
N14: Var[rE]=wETrasposto*V*wE | O14: {=MMULT(MMULT(TRANSPOSE(_xlfn.ANCHORARRAY(O8)),_xlfn.ANCHORARRAY(G3)),_xlfn.ANCHORARRAY(O8))} -> 0.00035048221
B16: Portafoglio ottimo | D16: =(1-D10*D8)*(O13-D8)/(D10*(O14+(O13-D8)^2)) -> 1501.7548 | E16: Nel portafoglio tangente | F16: quindi | G16: =O8*$D$16 -> 550.32579
B17: supponendo una ricchezza=1 | G17: =O9*$D$16 -> 1424.1492
G18: =O10*$D$16 -> -472.72018
D20: =(1-D16) -> -1500.7548 | E20: Nel titolo privo di rischio

Sheet ESPONENZIALE
D2: {=QUADRATICA!E2:E5} -> MEDIA rendimento annua | F2: VARIANZA | J2: e-rf*1
C3: {=QUADRATICA!D3:D5} -> APPLE | D3: 1.4828226 | F3: {=QUADRATICA!G3:I5} -> 0.00034259856 | G3: 0.00020087003 | H3: 0.00021196761 | J3: =D3-$G$8 -> 0.47282259
C4: AMAZON | D4: 1.6356261 | F4: 0.00020087003 | G4: 0.00034761112 | H4: 0.00023309145 | J4: =D4-$G$8 -> 0.6256261
C5: FACEBOOK | D5: 1.3336444 | F5: 0.00021196761 | G5: 0.00023309145 | H5: 0.00040685343 | J5: =D5-$G$8 -> 0.32364443
C8: a | D8: 0.15 | F8: rf | G8: =QUADRATICA!D8 -> 1.01
C10: x | D10: 1
C12: Funzione utilità | D12: 1-exp(-a*x)
C15: Portafoglio ottimo | D15: =(1/$D$8)*J3 -> 3.1521506
C16: 1/a*invV*(e-rf*1) | D16: =(1/$D$8)*J4 -> 4.1708407
D17: =(1/$D$8)*J5 -> 2.1576296
C19: Utilità | D19: =1-EXP(I19) -> 0.31272647 | H19: esponente | I19: =-D8*(D15*D3+G8*(1-D15))+D8^2*0.5*D15^2*F3 -> -0.37502291
D20: =1-EXP(I20) -> 0.4189044 | E20: Titolo B è il preferibile da scegliere | I20: =-D8*(D16*D4+G8*(1-D16))+D8^2*0.5*D16^2*G4 -> -0.54283999
D21: =1-EXP(I21) -> 0.22603174 | I21: =-D8*(D17*D5+G8*(1-D17))+D8^2*0.5*D17^2*H5 -> -0.25622441

Sheet Esercizio 3.21
C2: r | E2: V | M2: invV
C3: 1.16 | E3: 2 | F3: =-0.5*E3^0.5*F4^0.5 -> -1.4142136 | H3: 1 | J3: 1 | K3: 1 | M3: {=MINVERSE(E3:F4)} -> 0.66666667 | N3: 0.23570226
C4: 1.25 | E4: =F3 -> -1.4142136 | F4: 4 | H4: 1 | M4: 0.23570226 | N4: 0.33333333
C7: 1.13 | D7: rf
C9: MVP | D9: {=MMULT(_xlfn.ANCHORARRAY(M3),H3:H4)/(MMULT(MMULT(J3:K3,_xlfn.ANCHORARRAY(M3)),H3:H4))} -> 0.61327046 | H9: e-rf | I9: =C3-C7 -> 0.03 | K9: 0.01
D10: 0.38672954 | I10: =C4-C7 -> 0.12
C13: TAN | D13: {=MMULT(_xlfn.ANCHORARRAY(M3),I9:I10)/(MMULT(MMULT(J3:K3,_xlfn.ANCHORARRAY(M3)),I9:I10))} -> 0.50636149 | F13: {=TRANSPOSE(_xlfn.ANCHORARRAY(D13))} -> 0.50636149 | G13: 0.49363851 | K13: E | L13: {=MMULT(_xlfn.ANCHORARRAY(F13),C3:C4)} -> 1.2044275
D14: 0.49363851 | M14: Sul libro sono sbagliati i trasposti se ci fate caso
K15: var | L15: {=MMULT(MMULT(_xlfn.ANCHORARRAY(F13),E3:F4),_xlfn.ANCHORARRAY(D13))} -> 0.78052752
C16: OTT | D16: =(1-K9*C7)*(L13-C7)/(K9*(L15+(L13-C7)^2)) -> 9.3613444 | E16: nel port tangente | F16: =$D$16*D13 -> 4.7402243
F17: =$D$16*D14 -> 4.6211201
D19: =1-D16 -> -8.3613444 | E19: nel titolo privo di rischio

Sheet Esercizio 3.19
B2: 1.1 | D2: 0.1 | E2: 0 | F2: 0 | H2: {=MINVERSE(D2:F4)} -> 10 | I2: 0 | J2: 0 | K2: 1 | L2: 1 | M2: 1
B3: 1.13 | D3: 0 | E3: 0.15 | F3: 0 | H3: 0 | I3: 6.6666667 | J3: 0 | K3: 1
B4: 1.18 | D4: 0 | E4: 0 | F4: 0.3 | H4: 0 | I4: 0 | J4: 3.3333333
B6: 0.1 | C6: a | E6: e-rf | F6: =B2-$B$8 -> 0.05
F7: =B3-$B$8 -> 0.08
B8: 1.05 | C8: rf | F8: =B4-$B$8 -> 0.13
B11: OTT | C11: {=1/B6*MMULT(_xlfn.ANCHORARRAY(H2),F6:F8)} -> 5 | H11: esponente | I11: =-B6*(C11*B2+B8*(1-C11))+B6^2/2*C11^2*D2 -> -0.1175 | K11: utilità | L11: =1-EXP(I11) -> 0.11085949
C12: 5.3333333
C13: 4.3333333
C16: =1-EXP(H16) -> 0.15380039 | G16: esponente | H16: {=-B6*(MMULT(TRANSPOSE(B2:B4),_xlfn.ANCHORARRAY(C11))+B8*(1-SUM(_xlfn.ANCHORARRAY(C11))))+B6^2*0.5*MMULT(MMULT(TRANSPOSE(_xlfn.ANCHORARRAY(C11)),D2:F4),_xlfn.ANCHORARRAY(C11))} -> -0.167
