Workbook

Sheet Historical Simulation
A1: =_xll.Thomson.Reuters.AFOSpreadsheetFormulas.DSGRID("@AAPL,@AMZN,@FB"," ","-5Y","","D","RowHeader=true;ColHeader=true;Heading=true;LatestFirstValue=true;DispSeriesDescription=false;YearlyTSFormat=false;QuarterlyTSFormat=false","") -> #NAME? | B1: 42283
A2: End | B2: 44110
A3: Frequency | B3: D
A4: Name | B4: APPLE | C4: AMAZON.COM | D4: FACEBOOK CLASS A | E4: Portfolio Value [50 2 -20] | F4: GAIN | G4: LOSS | V4: Rendimento | W4: Apple | X4: Amazon | Y4: Facebook | AC4: Apple | AD4: Amazon | AE4: Facebook
A5: 44110 | B5: 113.16 | C5: 3099.96 | D5: 258.6599 | E5: =50*B5+2*C5-20*D5 -> 6684.722 | F5: =E5-E6 -> -245.68 | G5: =-F5 -> 245.68 | W5: =LN(B5/B6) -> -0.029088527 | X5: =LN(C5/C6) -> -0.03151157 | Y5: =LN(D5/D6) -> -0.022893749 | AC5: =AVERAGE(W5:W1303) -> 0.0010798907 | AD5: =AVERAGE(X5:X1303) -> 0.0013489245 | AE5: =AVERAGE(Y5:Y1303) -> 0.00078912042
A6: 44109 | B6: 116.5 | C6: 3199.2 | D6: 264.6499 | E6: =50*B6+2*C6-20*D6 -> 6930.402 | F6: =E6-E7 -> 228.2 | G6: =-F6 -> -228.2 | I6: Probability Loss is greater than | W6: =LN(B6/B7) -> 0.030326479 | X6: =LN(C6/C7) -> 0.023466495 | Y6: =LN(D6/D7) -> 0.01795737
A7: 44106 | B7: 113.02 | C7: 3125 | D7: 259.9399 | E7: =50*B7+2*C7-20*D7 -> 6702.202 | F7: =E7-E8 -> -247.22 | G7: =-F7 -> 247.22 | I7: 0 | J7: =COUNTIF($G:$G,">"&I7)/COUNT(G:G) -> 0.46959199 | W7: =LN(B7/B8) -> -0.032812656 | X7: =LN(C7/C8) -> -0.030338304 | Y7: =LN(D7/D8) -> -0.025411104
A8: 44105 | B8: 116.79 | C8: 3221.26 | D8: 266.6299 | E8: =50*B8+2*C8-20*D8 -> 6949.422 | F8: =E8-E9 -> 99.46 | G8: =-F8 -> -99.46 | I8: 10 | J8: =COUNTIF($G:$G,">"&I8)/COUNT(G:G) -> 0.34026174 | W8: =LN(B8/B9) -> 0.0084265331 | X8: =LN(C8/C9) -> 0.02277339 | Y8: =LN(D8/D9) -> 0.017899185
A9: 44104 | B9: 115.81 | C9: 3148.73 | D9: 261.8999 | E9: =50*B9+2*C9-20*D9 -> 6849.962 | F9: =E9-E10 -> 91.502 | G9: =-F9 -> -91.502 | I9: 20 | J9: =COUNTIF($G:$G,">"&I9)/COUNT(G:G) -> 0.26712856 | W9: =LN(B9/B10) -> 0.014963307 | X9: =LN(C9/C10) -> 0.0012234633 | Y9: =LN(D9/D10) -> 0.00041971404
A10: 44103 | B10: 114.09 | C10: 3144.88 | D10: 261.79 | E10: =50*B10+2*C10-20*D10 -> 6758.46 | F10: =E10-E11 -> -201.238 | G10: =-F10 -> 201.238 | I10: 30 | J10: =COUNTIF($G:$G,">"&I10)/COUNT(G:G) -> 0.2047729 | W10: =LN(B10/B11) -> -0.0075966312 | X10: =LN(C10/C11) -> -0.0092326414 | Y10: =LN(D10/D11) -> 0.019166816
A11: 44102 | B11: 114.96 | C11: 3174.05 | D11: 256.8201 | E11: =50*B11+2*C11-20*D11 -> 6959.698 | F11: =E11-E12 -> 251.838 | G11: =-F11 -> -251.838 | I11: 40 | J11: =COUNTIF($G:$G,">"&I11)/COUNT(G:G) -> 0.16551193 | W11: =LN(B11/B12) -> 0.02358849 | X11: =LN(C11/C12) -> 0.025178466 | Y11: =LN(D11/D12) -> 0.0078184262
A12: 44099 | B12: 112.28 | C12: 3095.13 | D12: 254.82 | E12: =50*B12+2*C12-20*D12 -> 6707.86 | F12: =E12-E13 -> 247.88 | G12: =-F12 -> -247.88 | I12: 50 | J12: =COUNTIF($G:$G,">"&I12)/COUNT(G:G) -> 0.13163972 | W12: =LN(B12/B13) -> 0.036829559 | X12: =LN(C12/C13) -> 0.024642616 | Y12: =LN(D12/D13) -> 0.020978265
A13: 44098 | B13: 108.22 | C13: 3019.79 | D13: 249.53 | E13: =50*B13+2*C13-20*D13 -> 6459.98 | F13: =E13-E14 -> 84.66 | G13: =-F13 -> -84.66 | I13: 60 | J13: =COUNTIF($G:$G,">"&I13)/COUNT(G:G) -> 0.10777521 | W13: =LN(B13/B14) -> 0.010216491 | X13: =LN(C13/C14) -> 0.0066216716 | Y13: =LN(D13/D14) -> 0.0020459339
A14: 44097 | B14: 107.12 | C14: 2999.86 | D14: 249.02 | E14: =50*B14+2*C14-20*D14 -> 6375.32 | F14: =E14-E15 -> -378.16 | G14: =-F14 -> 378.16 | I14: 70 | J14: =COUNTIF($G:$G,">"&I14)/COUNT(G:G) -> 0.095458045 | W14: =LN(B14/B15) -> -0.042851301 | X14: =LN(C14/C15) -> -0.042144648 | Y14: =LN(D14/D15) -> -0.022749458
A15: 44096 | B15: 111.81 | C15: 3128.99 | D15: 254.75 | E15: =50*B15+2*C15-20*D15 -> 6753.48 | F15: =E15-E16 -> 291.54 | G15: =-F15 -> -291.54 | I15: 80 | J15: =COUNTIF($G:$G,">"&I15)/COUNT(G:G) -> 0.089299461 | W15: =LN(B15/B16) -> 0.015593628 | X15: =LN(C15/C16) -> 0.055362229 | Y15: =LN(D15/D16) -> 0.02624927
A16: 44095 | B16: 110.08 | C16: 2960.47 | D16: 248.15 | E16: =50*B16+2*C16-20*D16 -> 6461.94 | F16: =E16-E17 -> 260.72 | G16: =-F16 -> -260.72 | I16: 90 | J16: =COUNTIF($G:$G,">"&I16)/COUNT(G:G) -> 0.073903002 | M16: VaR 95% | N16: =MIN(I20:I21) -> 112 | O16: In realtà è 114 perché è primo più piccolo di 5% | W16: =LN(B16/B17) -> 0.029874986 | X16: =LN(C16/C17) -> 0.001879846 | Y16: =LN(D16/D17) -> -0.017496652
A17: 44092 | B17: 106.84 | C17: 2954.91 | D17: 252.53 | E17: =50*B17+2*C17-20*D17 -> 6201.22 | F17: =E17-E18 -> -236.84 | G17: =-F17 -> 236.84 | I17: 100 | J17: =COUNTIF($G:$G,">"&I17)/COUNT(G:G) -> 0.061585835 | M17: VaR 99% | N17: =MIN(I42:I45) -> 242 | O17: In realtà è 246 | W17: =LN(B17/B18) -> -0.03223412 | X17: =LN(C17/C18) -> -0.018049869 | Y17: =LN(D17/D18) -> -0.00902736
A18: 44091 | B18: 110.34 | C18: 3008.73 | D18: 254.82 | E18: =50*B18+2*C18-20*D18 -> 6438.06 | F18: =E18-E19 -> -54.24 | G18: =-F18 -> 54.24 | I18: 110 | J18: =COUNTIF($G:$G,">"&I18)/COUNT(G:G) -> 0.05234796 | W18: =LN(B18/B19) -> -0.016092405 | X18: =LN(C18/C19) -> -0.022794461 | Y18: =LN(D18/D19) -> -0.033571853
A19: 44090 | B19: 112.13 | C19: 3078.1 | D19: 263.52 | E19: =50*B19+2*C19-20*D19 -> 6492.3 | F19: =E19-E20 -> -148.562 | G19: =-F19 -> 148.562 | I19: 111 | J19: =COUNTIF($G:$G,">"&I19)/COUNT(G:G) -> 0.050808314 | W19: =LN(B19/B20) -> -0.029957878 | X19: =LN(C19/C20) -> -0.02503407 | Y19: =LN(D19/D20) -> -0.03321536
A20: 44089 | B20: 115.54 | C20: 3156.13 | D20: 272.4199 | E20: =50*B20+2*C20-20*D20 -> 6640.862 | F20: =E20-E21 -> -9.83 | G20: =-F20 -> 9.83 | I20: 112 | J20: =COUNTIF($G:$G,">"&I20)/COUNT(G:G) -> 0.050038491 | K20: =J20 -> 0.050038491 | W20: =LN(B20/B21) -> 0.0016024603 | X20: =LN(C20/C21) -> 0.016986876 | Y20: =LN(D20/D21) -> 0.023284942
A21: 44088 | B21: 115.355 | C21: 3102.97 | D21: 266.1499 | E21: =50*B21+2*C21-20*D21 -> 6650.692 | F21: =E21-E22 -> 150.454 | G21: =-F21 -> -150.454 | I21: 113 | J21: =COUNTIF($G:$G,">"&I21)/COUNT(G:G) -> 0.050038491 | K21: =J21 -> 0.050038491 | W21: =LN(B21/B22) -> 0.029515459 | X21: =LN(C21/C22) -> -0.0042610115 | Y21: =LN(D21/D22) -> -0.0017276076
A22: 44085 | B22: 112 | C22: 3116.22 | D22: 266.6101 | E22: =50*B22+2*C22-20*D22 -> 6500.238 | F22: =E22-E23 -> -162.68 | G22: =-F22 -> 162.68 | I22: 114 | J22: =COUNTIF($G:$G,">"&I22)/COUNT(G:G) -> 0.049268668 | W22: =LN(B22/B23) -> -0.013215856 | X22: =LN(C22/C23) -> -0.018721549 | Y22: =LN(D22/D23) -> -0.0055358265
A23: 44084 | B23: 113.49 | C23: 3175.11 | D23: 268.0901 | E23: =50*B23+2*C23-20*D23 -> 6662.918 | F23: =E23-E24 -> -265.902 | G23: =-F23 -> 265.902 | I23: 115 | J23: =COUNTIF($G:$G,">"&I23)/COUNT(G:G) -> 0.048498845 | W23: =LN(B23/B24) -> -0.033190517 | X23: =LN(C23/C24) -> -0.029022541 | Y23: =LN(D23/D24) -> -0.020782568
A24: 44083 | B24: 117.32 | C24: 3268.61 | D24: 273.72 | E24: =50*B24+2*C24-20*D24 -> 6928.82 | F24: =E24-E25 -> 411.338 | G24: =-F24 -> -411.338 | I24: 116 | J24: =COUNTIF($G:$G,">"&I24)/COUNT(G:G) -> 0.047729022 | W24: =LN(B24/B25) -> 0.039111616 | X24: =LN(C24/C25) -> 0.03701316 | Y24: =LN(D24/D25) -> 0.0093970023
A25: 44082 | B25: 112.82 | C25: 3149.84 | D25: 271.1599 | E25: =50*B25+2*C25-20*D25 -> 6517.482 | F25: =E25-E26 -> -465.158 | G25: =-F25 -> 465.158 | I25: 117 | J25: =COUNTIF($G:$G,">"&I25)/COUNT(G:G) -> 0.046959199 | W25: =LN(B25/B26) -> -0.069666284 | X25: =LN(C25/C26) -> -0.044939177 | Y25: =LN(D25/D26) -> -0.041783695
A26: 44078 | B26: 120.96 | C26: 3294.62 | D26: 282.73 | E26: =50*B26+2*C26-20*D26 -> 6982.64 | F26: =E26-E27 -> 25.042 | G26: =-F26 -> -25.042 | I26: 118 | J26: =COUNTIF($G:$G,">"&I26)/COUNT(G:G) -> 0.046959199 | W26: =LN(B26/B27) -> 0.00066159447 | X26: =LN(C26/C27) -> -0.022028261 | Y26: =LN(D26/D27) -> -0.029243518
A27: 44077 | B27: 120.88 | C27: 3368 | D27: 291.1201 | E27: =50*B27+2*C27-20*D27 -> 6957.598 | F27: =E27-E28 -> -625.302 | G27: =-F27 -> 625.302 | I27: 119 | J27: =COUNTIF($G:$G,">"&I27)/COUNT(G:G) -> 0.046189376 | W27: =LN(B27/B28) -> -0.083447788 | X27: =LN(C27/C28) -> -0.047389455 | Y27: =LN(D27/D28) -> -0.038345381
A28: 44076 | B28: 131.4 | C28: 3531.45 | D28: 302.5 | E28: =50*B28+2*C28-20*D28 -> 7582.9 | F28: =E28-E29 -> -215.542 | G28: =-F28 -> 215.542 | I28: 120 | J28: =COUNTIF($G:$G,">"&I28)/COUNT(G:G) -> 0.046189376 | W28: =LN(B28/B29) -> -0.020936076 | X28: =LN(C28/C29) -> 0.0091970432 | Y28: =LN(D28/D29) -> 0.023615845
A29: 44075 | B29: 134.18 | C29: 3499.12 | D29: 295.4399 | E29: =50*B29+2*C29-20*D29 -> 7798.442 | F29: =E29-E30 -> 308.522 | G29: =-F29 -> -308.522 | I29: 130 | J29: =COUNTIF($G:$G,">"&I29)/COUNT(G:G) -> 0.040030793 | W29: =LN(B29/B30) -> 0.039059748 | X29: =LN(C29/C30) -> 0.013859055 | Y29: =LN(D29/D30) -> 0.0076104621
A30: 44074 | B30: 129.04 | C30: 3450.96 | D30: 293.2 | E30: =50*B30+2*C30-20*D30 -> 7489.92 | F30: =E30-E31 -> 319.143 | G30: =-F30 -> -319.143 | I30: 140 | J30: =COUNTIF($G:$G,">"&I30)/COUNT(G:G) -> 0.037721324 | W30: =LN(B30/B31) -> 0.033349884 | X30: =LN(C30/C31) -> 0.01434775 | Y30: =LN(D30/D31) -> -0.001567325
A31: 44071 | B31: 124.8075 | C31: 3401.8 | D31: 293.6599 | E31: =50*B31+2*C31-20*D31 -> 7170.777 | F31: =E31-E32 -> -15.323 | G31: =-F31 -> 15.323 | I31: 150 | J31: =COUNTIF($G:$G,">"&I31)/COUNT(G:G) -> 0.033872209 | W31: =LN(B31/B32) -> -0.0016211838 | X31: =LN(C31/C32) -> 0.00052927168 | Y31: =LN(D31/D32) -> 0.0014991145
A32: 44070 | B32: 125.01 | C32: 3400 | D32: 293.22 | E32: =50*B32+2*C32-20*D32 -> 7186.1 | F32: =E32-E33 -> 54.473 | G32: =-F32 -> -54.473 | I32: 160 | J32: =COUNTIF($G:$G,">"&I32)/COUNT(G:G) -> 0.032332564 | W32: =LN(B32/B33) -> -0.012026424 | X32: =LN(C32/C33) -> -0.012233686 | Y32: =LN(D32/D33) -> -0.035808095
A33: 44069 | B33: 126.5225 | C33: 3441.85 | D33: 303.9099 | E33: =50*B33+2*C33-20*D33 -> 7131.627 | F33: =E33-E34 -> -186.201 | G33: =-F33 -> 186.201 | I33: 170 | J33: =COUNTIF($G:$G,">"&I33)/COUNT(G:G) -> 0.02617398 | W33: =LN(B33/B34) -> 0.013507402 | X33: =LN(C33/C34) -> 0.028097082 | Y33: =LN(D33/D34) -> 0.079017025
... A41: 44057 | B41: 114.9075 | C41: 3148.02 | D41: 261.24 | E41: =50*B41+2*C41-20*D41 -> 6816.615 | F41: =E41-E42 -> -29.925 | G41: =-F41 -> 29.925 | I41: 241 | J41: =COUNTIF($G:$G,">"&I41)/COUNT(G:G) -> 0.010777521 | W41: =LN(B41/B42) -> -0.00089162423 | X41: =LN(C41/C42) -> -0.0041210766 | Y41: =LN(D41/D42) -> -0.00022964749
A42: 44056 | B42: 115.01 | C42: 3161.02 | D42: 261.3 | E42: =50*B42+2*C42-20*D42 -> 6846.54 | F42: =E42-E43 -> 69.358 | G42: =-F42 -> -69.358 | I42: 242 | J42: =COUNTIF($G:$G,">"&I42)/COUNT(G:G) -> 0.010007698 | K42: =J42 -> 0.010007698 | W42: =LN(B42/B43) -> 0.017542771 | X42: =LN(C42/C43) -> -0.00038587691 | Y42: =LN(D42/D43) -> 0.0054110927
A43: 44055 | B43: 113.01 | C43: 3162.24 | D43: 259.8899 | E43: =50*B43+2*C43-20*D43 -> 6777.182 | F43: =E43-E44 -> 269.69 | G43: =-F43 -> -269.69 | I43: 243 | J43: =COUNTIF($G:$G,">"&I43)/COUNT(G:G) -> 0.010007698 | K43: =J43 -> 0.010007698 | W43: =LN(B43/B44) -> 0.032693966 | X43: =LN(C43/C44) -> 0.026133531 | Y43: =LN(D43/D44) -> 0.014573342
A44: 44054 | B44: 109.375 | C44: 3080.67 | D44: 256.1299 | E44: =50*B44+2*C44-20*D44 -> 6507.492 | F44: =E44-E45 -> -165.198 | G44: =-F44 -> 165.198 | I44: 244 | J44: =COUNTIF($G:$G,">"&I44)/COUNT(G:G) -> 0.010007698 | K44: =J44 -> 0.010007698 | W44: =LN(B44/B45) -> -0.03019017 | X44: =LN(C44/C45) -> -0.021671049 | Y44: =LN(D44/D45) -> -0.026469295
A45: 44053 | B45: 112.7274 | C45: 3148.16 | D45: 263 | E45: =50*B45+2*C45-20*D45 -> 6672.69 | F45: =E45-E46 -> 150.943 | G45: =-F45 -> -150.943 | I45: 245 | J45: =COUNTIF($G:$G,">"&I45)/COUNT(G:G) -> 0.010007698 | K45: =J45 -> 0.010007698 | W45: =LN(B45/B46) -> 0.014429313 | X45: =LN(C45/C46) -> -0.0061118497 | Y45: =LN(D45/D46) -> -0.020473021
A46: 44050 | B46: 111.1125 | C46: 3167.46 | D46: 268.4399 | E46: =50*B46+2*C46-20*D46 -> 6521.747 | F46: =E46-E47 -> -317.778 | G46: =-F46 -> 317.778 | I46: 246 | J46: =COUNTIF($G:$G,">"&I46)/COUNT(G:G) -> 0.0092378753 | W46: =LN(B46/B47) -> -0.024799618 | X46: =LN(C46/C47) -> -0.018002945 | Y46: =LN(D46/D47) -> 0.011841181
A47: 44049 | B47: 113.9025 | C47: 3225 | D47: 265.28 | E47: =50*B47+2*C47-20*D47 -> 6839.525 | F47: =E47-E48 -> -91.26 | G47: =-F47 -> 91.26 | I47: 247 | J47: =COUNTIF($G:$G,">"&I47)/COUNT(G:G) -> 0.0084680523 | W47: =LN(B47/B48) -> 0.034294433 | X47: =LN(C47/C48) -> 0.0062114995 | Y47: =LN(D47/D48) -> 0.062851164
...

Sheet Punto 1
A1: =_xll.Thomson.Reuters.AFOSpreadsheetFormulas.DSGRID("@AAPL,@AMZN,@FB"," ","-5Y","","D","RowHeader=true;ColHeader=true;Heading=true;LatestFirstValue=true;DispSeriesDescription=false;YearlyTSFormat=false;QuarterlyTSFormat=false","") -> #NAME? | B1: 42283
A2: End | B2: 44110
A3: Frequency | B3: D
A4: Name | B4: APPLE | C4: AMAZON.COM | D4: Portfolio Value [a,1-a] | E4: GAIN | F4: LOSS
A5: 44110 | B5: 113.16 | C5: 3099.96 | D5: =$M$16*B5+(1-$M$16)*C5 -> 1691.1384 | E5: =D5-D6 -> -54.005638 | F5: =-E5 -> 54.005638
A6: 44109 | B6: 116.5 | C6: 3199.2 | D6: =$M$16*B6+(1-$M$16)*C6 -> 1745.144 | E6: =D6-D7 -> 40.842606 | F6: =-E6 -> -40.842606 | H6: Probability Loss is greater than
A7: 44106 | B7: 113.02 | C7: 3125 | D7: =$M$16*B7+(1-$M$16)*C7 -> 1704.3014 | E7: =D7-D8 -> -52.634076 | F7: =-E7 -> 52.634076 | H7: 1 | I7: =COUNTIF($F:$F,">"&H7)/COUNT(F:F) -> 0.38722094
A8: 44105 | B8: 116.79 | C8: 3221.26 | D8: =$M$16*B8+(1-$M$16)*C8 -> 1756.9355 | E8: =D8-D9 -> 38.78111 | F8: =-E8 -> -38.78111 | H8: 2 | I8: =COUNTIF($F:$F,">"&H8)/COUNT(F:F) -> 0.32948422 | L8: Rendimento previsto | M8: =M16*'Historical Simulation'!AC5+'Punto 2'!N16*'Historical Simulation'!AD5 -> 0.00085485972
A9: 44104 | B9: 115.81 | C9: 3148.73 | D9: =$M$16*B9+(1-$M$16)*C9 -> 1718.1544 | E9: =D9-D10 -> 2.8453161 | F9: =-E9 -> -2.8453161 | H9: 3 | I9: =COUNTIF($F:$F,">"&H9)/COUNT(F:F) -> 0.28714396
A10: 44103 | B10: 114.09 | C10: 3144.88 | D10: =$M$16*B10+(1-$M$16)*C10 -> 1715.3091 | E10: =D10-D11 -> -15.821382 | F10: =-E10 -> 15.821382 | H10: 4 | I10: =COUNTIF($F:$F,">"&H10)/COUNT(F:F) -> 0.2517321
A11: 44102 | B11: 114.96 | C11: 3174.05 | D11: =$M$16*B11+(1-$M$16)*C11 -> 1731.1305 | E11: =D11-D12 -> 42.958918 | F11: =-E11 -> -42.958918 | H11: 5 | I11: =COUNTIF($F:$F,">"&H11)/COUNT(F:F) -> 0.22786759
A12: 44099 | B12: 112.28 | C12: 3095.13 | D12: =$M$16*B12+(1-$M$16)*C12 -> 1688.1715 | E12: =D12-D13 -> 41.718464 | F12: =-E12 -> -41.718464 | H12: 6 | I12: =COUNTIF($F:$F,">"&H12)/COUNT(F:F) -> 0.19861432
A13: 44098 | B13: 108.22 | C13: 3019.79 | D13: =$M$16*B13+(1-$M$16)*C13 -> 1646.4531 | E13: =D13-D14 -> 11.048217 | F13: =-E13 -> -11.048217 | H13: 7 | I13: =COUNTIF($F:$F,">"&H13)/COUNT(F:F) -> 0.17705928
A14: 44097 | B14: 107.12 | C14: 2999.86 | D14: =$M$16*B14+(1-$M$16)*C14 -> 1635.4049 | E14: =D14-D15 -> -70.433817 | F14: =-E14 -> 70.433817 | H14: 8 | I14: =COUNTIF($F:$F,">"&H14)/COUNT(F:F) -> 0.15704388
A15: 44096 | B15: 111.81 | C15: 3128.99 | D15: =$M$16*B15+(1-$M$16)*C15 -> 1705.8387 | E15: =D15-D16 -> 89.848059 | F15: =-E15 -> -89.848059 | H15: 9 | I15: =COUNTIF($F:$F,">"&H15)/COUNT(F:F) -> 0.14934565
A16: 44095 | B16: 110.08 | C16: 2960.47 | D16: =$M$16*B16+(1-$M$16)*C16 -> 1615.9906 | E16: =D16-D17 -> 4.4656964 | F16: =-E16 -> -4.4656964 | H16: 10 | I16: =COUNTIF($F:$F,">"&H16)/COUNT(F:F) -> 0.13394919 | L16: a | M16: 0.4716826 | N16: =1-M16 -> 0.5283174
A17: 44092 | B17: 106.84 | C17: 2954.91 | D17: =$M$16*B17+(1-$M$16)*C17 -> 1611.5249 | E17: =D17-D18 -> -30.084931 | F17: =-E17 -> 30.084931 | H17: 11 | I17: =COUNTIF($F:$F,">"&H17)/COUNT(F:F) -> 0.12394149 | L17: VaR 95% | M17: 28
A18: 44091 | B18: 110.34 | C18: 3008.73 | D18: =$M$16*B18+(1-$M$16)*C18 -> 1641.6099 | E18: =D18-D19 -> -37.49369 | F18: =-E18 -> 37.49369 | H18: 12 | I18: =COUNTIF($F:$F,">"&H18)/COUNT(F:F) -> 0.12163202
A19: 44090 | B19: 112.13 | C19: 3078.1 | D19: =$M$16*B19+(1-$M$16)*C19 -> 1679.1035 | E19: =D19-D20 -> -42.833044 | F19: =-E19 -> 42.833044 | H19: 13 | I19: =COUNTIF($F:$F,">"&H19)/COUNT(F:F) -> 0.11008468
A20: 44089 | B20: 115.54 | C20: 3156.13 | D20: =$M$16*B20+(1-$M$16)*C20 -> 1721.9366 | E20: =D20-D21 -> 28.172614 | F20: =-E20 -> -28.172614 | H20: 14 | I20: =COUNTIF($F:$F,">"&H20)/COUNT(F:F) -> 0.1039261
A21: 44088 | B21: 115.355 | C21: 3102.97 | D21: =$M$16*B21+(1-$M$16)*C21 -> 1693.764 | E21: =D21-D22 -> -5.4177104 | F21: =-E21 -> 5.4177104 | H21: 15 | I21: =COUNTIF($F:$F,">"&H21)/COUNT(F:F) -> 0.099307159
A22: 44085 | B22: 112 | C22: 3116.22 | D22: =$M$16*B22+(1-$M$16)*C22 -> 1699.1817 | E22: =D22-D23 -> -31.815419 | F22: =-E22 -> 31.815419 | H22: 16 | I22: =COUNTIF($F:$F,">"&H22)/COUNT(F:F) -> 0.09160893
A23: 44084 | B23: 113.49 | C23: 3175.11 | D23: =$M$16*B23+(1-$M$16)*C23 -> 1730.9971 | E23: =D23-D24 -> -51.204221 | F23: =-E23 -> 51.204221 | H23: 17 | I23: =COUNTIF($F:$F,">"&H23)/COUNT(F:F) -> 0.086220169
A24: 44083 | B24: 117.32 | C24: 3268.61 | D24: =$M$16*B24+(1-$M$16)*C24 -> 1782.2013 | E24: =D24-D25 -> 64.870829 | F24: =-E24 -> -64.870829 | H24: 18 | I24: =COUNTIF($F:$F,">"&H24)/COUNT(F:F) -> 0.080061586
A25: 44082 | B25: 112.82 | C25: 3149.84 | D25: =$M$16*B25+(1-$M$16)*C25 -> 1717.3305 | E25: =D25-D26 -> -80.329289 | F25: =-E25 -> 80.329289 | H25: 19 | I25: =COUNTIF($F:$F,">"&H25)/COUNT(F:F) -> 0.076212471
A26: 44078 | B26: 120.96 | C26: 3294.62 | D26: =$M$16*B26+(1-$M$16)*C26 -> 1797.6598 | E26: =D26-D27 -> -38.730196 | F26: =-E26 -> 38.730196 | H26: 20 | I26: =COUNTIF($F:$F,">"&H26)/COUNT(F:F) -> 0.071593533
A27: 44077 | B27: 120.88 | C27: 3368 | D27: =$M$16*B27+(1-$M$16)*C27 -> 1836.39 | E27: =D27-D28 -> -91.315579 | F27: =-E27 -> 91.315579 | H27: 21 | I27: =COUNTIF($F:$F,">"&H27)/COUNT(F:F) -> 0.06543495
A28: 44076 | B28: 131.4 | C28: 3531.45 | D28: =$M$16*B28+(1-$M$16)*C28 -> 1927.7056 | E28: =D28-D29 -> 15.769224 | F28: =-E28 -> -15.769224 | H28: 22 | I28: =COUNTIF($F:$F,">"&H28)/COUNT(F:F) -> 0.064665127
A29: 44075 | B29: 134.18 | C29: 3499.12 | D29: =$M$16*B29+(1-$M$16)*C29 -> 1911.9363 | E29: =D29-D30 -> 27.868214 | F29: =-E29 -> -27.868214 | H29: 23 | I29: =COUNTIF($F:$F,">"&H29)/COUNT(F:F) -> 0.060046189
... A32: 44070 | B32: 125.01 | C32: 3400 | D32: =$M$16*B32+(1-$M$16)*C32 -> 1855.2442 | E32: =D32-D33 -> -22.823503 | F32: =-E32 -> 22.823503 | H32: 26 | I32: =COUNTIF($F:$F,">"&H32)/COUNT(F:F) -> 0.053117783
A33: 44069 | B33: 126.5225 | C33: 3441.85 | D33: =$M$16*B33+(1-$M$16)*C33 -> 1878.0677 | E33: =D33-D34 -> 51.181028 | F33: =-E33 -> -51.181028 | H33: 27 | I33: =COUNTIF($F:$F,">"&H33)/COUNT(F:F) -> 0.051578137 | J33: Numero di numeri più grandi | K33: Salti dal precedente | L33: Probabilità salto | M33: E[salto]
A34: 44068 | B34: 124.825 | C34: 3346.49 | D34: =$M$16*B34+(1-$M$16)*C34 -> 1826.8867 | E34: =D34-D35 -> 20.133216 | F34: =-E34 -> -20.133216 | H34: 28 | I34: =COUNTIF($F:$F,">"&H34)/COUNT(F:F) -> 0.049268668 | J34: =COUNTIF($F:$F,">"&H34) -> 64 | K34: =J34-J35 -> 3 | L34: =K34/COUNT(F:F) -> 0.0023094688 | M34: =H34*L34 -> 0.064665127
A35: 44067 | B35: 125.8575 | C35: 3307.46 | D35: =$M$16*B35+(1-$M$16)*C35 -> 1806.7534 | E35: =D35-D36 -> 12.715565 | F35: =-E35 -> -12.715565 | H35: 29 | I35: =COUNTIF($F:$F,">"&H35)/COUNT(F:F) -> 0.046959199 | J35: =COUNTIF($F:$F,">"&H35) -> 61 | K35: =J35-J36 -> 3 | L35: =K35/COUNT(F:F) -> 0.0023094688 | M35: =H35*L35 -> 0.066974596
A36: 44064 | B36: 124.37 | C36: 3284.72 | D36: =$M$16*B36+(1-$M$16)*C36 -> 1794.0379 | E36: =D36-D37 -> -3.8083096 | F36: =-E36 -> 3.8083096 | H36: 30 | I36: =COUNTIF($F:$F,">"&H36)/COUNT(F:F) -> 0.044649731 | J36: =COUNTIF($F:$F,">"&H36) -> 58 | K36: =J36-J37 -> 6 | L36: =K36/COUNT(F:F) -> 0.0046189376 | M36: =H36*L36 -> 0.13856813
A37: 44063 | B37: 118.275 | C37: 3297.37 | D37: =$M$16*B37+(1-$M$16)*C37 -> 1797.8462 | E37: =D37-D38 -> 20.700674 | F37: =-E37 -> -20.700674 | H37: 31 | I37: =COUNTIF($F:$F,">"&H37)/COUNT(F:F) -> 0.040030793 | J37: =COUNTIF($F:$F,">"&H37) -> 52 | K37: =J37-J38 -> 6 | L37: =K37/COUNT(F:F) -> 0.0046189376 | M37: =H37*L37 -> 0.14318707
A38: 44062 | B38: 115.7075 | C38: 3260.48 | D38: =$M$16*B38+(1-$M$16)*C38 -> 1777.1455 | E38: =D38-D39 -> -27.409394 | F38: =-E38 -> 27.409394 | H38: 32 | I38: =COUNTIF($F:$F,">"&H38)/COUNT(F:F) -> 0.035411855 | J38: =COUNTIF($F:$F,">"&H38) -> 46 | K38: =J38-J39 -> 2 | L38: =K38/COUNT(F:F) -> 0.0015396459 | M38: =H38*L38 -> 0.049268668
A39: 44061 | B39: 115.5625 | C39: 3312.49 | D39: =$M$16*B39+(1-$M$16)*C39 -> 1804.5549 | E39: =D39-D40 -> 69.173984 | F39: =-E39 -> -69.173984 | H39: 33 | I39: =COUNTIF($F:$F,">"&H39)/COUNT(F:F) -> 0.033872209 | J39: =COUNTIF($F:$F,">"&H39) -> 44 | K39: =J39-J40 -> 4 | L39: =K39/COUNT(F:F) -> 0.0030792918 | M39: =H39*L39 -> 0.10161663
A40: 44060 | B40: 114.6075 | C40: 3182.41 | D40: =$M$16*B40+(1-$M$16)*C40 -> 1735.3809 | E40: =D40-D41 -> 18.02733 | F40: =-E40 -> -18.02733 | H40: 34 | I40: =COUNTIF($F:$F,">"&H40)/COUNT(F:F) -> 0.030792918 | J40: =COUNTIF($F:$F,">"&H40) -> 40 | K40: =J40-J41 -> 2 | L40: =K40/COUNT(F:F) -> 0.0015396459 | M40: =H40*L40 -> 0.05234796
A41: 44057 | B41: 114.9075 | C41: 3148.02 | D41: =$M$16*B41+(1-$M$16)*C41 -> 1717.3536 | E41: =D41-D42 -> -6.9164736 | F41: =-E41 -> 6.9164736 | H41: 35 | I41: =COUNTIF($F:$F,">"&H41)/COUNT(F:F) -> 0.029253272 | J41: =COUNTIF($F:$F,">"&H41) -> 38 | K41: =J41-J42 -> 3 | L41: =K41/COUNT(F:F) -> 0.0023094688 | M41: =H41*L41 -> 0.080831409
A42: 44056 | B42: 115.01 | C42: 3161.02 | D42: =$M$16*B42+(1-$M$16)*C42 -> 1724.2701 | E42: =D42-D43 -> 0.29881798 | F42: =-E42 -> -0.29881798 | H42: 36 | I42: =COUNTIF($F:$F,">"&H42)/COUNT(F:F) -> 0.026943803 | J42: =COUNTIF($F:$F,">"&H42) -> 35 | K42: =J42-J43 -> 1 | L42: =K42/COUNT(F:F) -> 0.00076982294 | M42: =H42*L42 -> 0.027713626
...

Sheet Punto 2
A1: =_xll.Thomson.Reuters.AFOSpreadsheetFormulas.DSGRID("@AAPL,@AMZN,@FB"," ","-5Y","","D","RowHeader=true;ColHeader=true;Heading=true;LatestFirstValue=true;DispSeriesDescription=false;YearlyTSFormat=false;QuarterlyTSFormat=false","") -> #NAME? | B1: 42283
A2: End | B2: 44110
A3: Frequency | B3: D
A4: Name | B4: APPLE | C4: AMAZON.COM | D4: Portfolio Value [a,1-a] | E4: GAIN | F4: LOSS
A5: 44110 | B5: 113.16 | C5: 3099.96 | D5: =$M$16*B5+(1-$M$16)*C5 -> 878.15588 | E5: =D5-D6 -> -27.902443 | F5: =-E5 -> 27.902443
A6: 44109 | B6: 116.5 | C6: 3199.2 | D6: =$M$16*B6+(1-$M$16)*C6 -> 906.05833 | E6: =D6-D7 -> 21.593201 | F6: =-E6 -> -21.593201 | H6: Probability Loss is greater than
A7: 44106 | B7: 113.02 | C7: 3125 | D7: =$M$16*B7+(1-$M$16)*C7 -> 884.46513 | E7: =D7-D8 -> -27.459055 | F7: =-E7 -> 27.459055 | H7: 1 | I7: =COUNTIF($F:$F,">"&H7)/COUNT(F:F) -> 0.3287144
A8: 44105 | B8: 116.79 | C8: 3221.26 | D8: =$M$16*B8+(1-$M$16)*C8 -> 911.92418 | E8: =D8-D9 -> 19.305785 | F8: =-E8 -> -19.305785 | H8: 2 | I8: =COUNTIF($F:$F,">"&H8)/COUNT(F:F) -> 0.25019246 | L8: Rendimento previsto | M8: =M16*'Historical Simulation'!AC5+'Punto 2'!N16*'Historical Simulation'!AD5 -> 0.0011487971
A9: 44104 | B9: 115.81 | C9: 3148.73 | D9: =$M$16*B9+(1-$M$16)*C9 -> 892.6184 | E9: =D9-D10 -> 2.2655475 | F9: =-E9 -> -2.2655475 | H9: 3 | I9: =COUNTIF($F:$F,">"&H9)/COUNT(F:F) -> 0.19938414
A10: 44103 | B10: 114.09 | C10: 3144.88 | D10: =$M$16*B10+(1-$M$16)*C10 -> 890.35285 | E10: =D10-D11 -> -8.1183539 | F10: =-E10 -> 8.1183539 | H10: 4 | I10: =COUNTIF($F:$F,">"&H10)/COUNT(F:F) -> 0.15704388
A11: 44102 | B11: 114.96 | C11: 3174.05 | D11: =$M$16*B11+(1-$M$16)*C11 -> 898.4712 | E11: =D11-D12 -> 22.207014 | F11: =-E11 -> -22.207014 | H11: 5 | I11: =COUNTIF($F:$F,">"&H11)/COUNT(F:F) -> 0.13548884
A12: 44099 | B12: 112.28 | C12: 3095.13 | D12: =$M$16*B12+(1-$M$16)*C12 -> 876.26419 | E12: =D12-D13 -> 22.316631 | F12: =-E12 -> -22.316631 | H12: 6 | I12: =COUNTIF($F:$F,">"&H12)/COUNT(F:F) -> 0.1208622
A13: 44098 | B13: 108.22 | C13: 3019.79 | D13: =$M$16*B13+(1-$M$16)*C13 -> 853.94756 | E13: =D13-D14 -> 5.9228447 | F13: =-E13 -> -5.9228447 | H13: 7 | I13: =COUNTIF($F:$F,">"&H13)/COUNT(F:F) -> 0.10546574
A14: 44097 | B14: 107.12 | C14: 2999.86 | D14: =$M$16*B14+(1-$M$16)*C14 -> 848.02471 | E14: =D14-D15 -> -36.562267 | F14: =-E14 -> 36.562267 | H14: 8 | I14: =COUNTIF($F:$F,">"&H14)/COUNT(F:F) -> 0.090069284
A15: 44096 | B15: 111.81 | C15: 3128.99 | D15: =$M$16*B15+(1-$M$16)*C15 -> 884.58698 | E15: =D15-D16 -> 44.449186 | F15: =-E15 -> -44.449186 | H15: 9 | I15: =COUNTIF($F:$F,">"&H15)/COUNT(F:F) -> 0.082371055
A16: 44095 | B16: 110.08 | C16: 2960.47 | D16: =$M$16*B16+(1-$M$16)*C16 -> 840.13779 | E16: =D16-D17 -> 3.8342113 | F16: =-E16 -> -3.8342113 | H16: 10 | I16: =COUNTIF($F:$F,">"&H16)/COUNT(F:F) -> 0.070053888 | L16: a | M16: 0.74387442 | N16: =1-M16 -> 0.25612558
A17: 44092 | B17: 106.84 | C17: 2954.91 | D17: =$M$16*B17+(1-$M$16)*C17 -> 836.30358 | E17: =D17-D18 -> -16.388239 | F17: =-E17 -> 16.388239 | H17: 11 | I17: =COUNTIF($F:$F,">"&H17)/COUNT(F:F) -> 0.06543495 | L17: VaR 99% | M17: 28
A18: 44091 | B18: 110.34 | C18: 3008.73 | D18: =$M$16*B18+(1-$M$16)*C18 -> 852.69182 | E18: =D18-D19 -> -19.098967 | F18: =-E18 -> 19.098967 | H18: 12 | I18: =COUNTIF($F:$F,">"&H18)/COUNT(F:F) -> 0.055427252
A19: 44090 | B19: 112.13 | C19: 3078.1 | D19: =$M$16*B19+(1-$M$16)*C19 -> 871.79079 | E19: =D19-D20 -> -22.522091 | F19: =-E19 -> 22.522091 | H19: 13 | I19: =COUNTIF($F:$F,">"&H19)/COUNT(F:F) -> 0.053887606
A20: 44089 | B20: 115.54 | C20: 3156.13 | D20: =$M$16*B20+(1-$M$16)*C20 -> 894.31288 | E20: =D20-D21 -> 13.753253 | F20: =-E20 -> -13.753253 | H20: 14 | I20: =COUNTIF($F:$F,">"&H20)/COUNT(F:F) -> 0.049268668
A21: 44088 | B21: 115.355 | C21: 3102.97 | D21: =$M$16*B21+(1-$M$16)*C21 -> 880.55963 | E21: =D21-D22 -> -0.89796526 | F21: =-E21 -> 0.89796526 | H21: 15 | I21: =COUNTIF($F:$F,">"&H21)/COUNT(F:F) -> 0.045419554
A22: 44085 | B22: 112 | C22: 3116.22 | D22: =$M$16*B22+(1-$M$16)*C22 -> 881.45759 | E22: =D22-D23 -> -16.191608 | F22: =-E22 -> 16.191608 | H22: 16 | I22: =COUNTIF($F:$F,">"&H22)/COUNT(F:F) -> 0.040030793
A23: 44084 | B23: 113.49 | C23: 3175.11 | D23: =$M$16*B23+(1-$M$16)*C23 -> 897.6492 | E23: =D23-D24 -> -26.796781 | F23: =-E23 -> 26.796781 | H23: 17 | I23: =COUNTIF($F:$F,">"&H23)/COUNT(F:F) -> 0.032332564
A24: 44083 | B24: 117.32 | C24: 3268.61 | D24: =$M$16*B24+(1-$M$16)*C24 -> 924.44598 | E24: =D24-D25 -> 33.76747 | F24: =-E24 -> -33.76747 | H24: 18 | I24: =COUNTIF($F:$F,">"&H24)/COUNT(F:F) -> 0.028483449
A25: 44082 | B25: 112.82 | C25: 3149.84 | D25: =$M$16*B25+(1-$M$16)*C25 -> 890.67851 | E25: =D25-D26 -> -43.136999 | F25: =-E25 -> 43.136999 | H25: 19 | I25: =COUNTIF($F:$F,">"&H25)/COUNT(F:F) -> 0.024634334
A26: 44078 | B26: 120.96 | C26: 3294.62 | D26: =$M$16*B26+(1-$M$16)*C26 -> 933.81551 | E26: =D26-D27 -> -18.734985 | F26: =-E26 -> 18.734985 | H26: 20 | I26: =COUNTIF($F:$F,">"&H26)/COUNT(F:F) -> 0.020785219
A27: 44077 | B27: 120.88 | C27: 3368 | D27: =$M$16*B27+(1-$M$16)*C27 -> 952.55049 | E27: =D27-D28 -> -49.689285 | F27: =-E27 -> 49.689285 | H27: 21 | I27: =COUNTIF($F:$F,">"&H27)/COUNT(F:F) -> 0.020015396
A28: 44076 | B28: 131.4 | C28: 3531.45 | D28: =$M$16*B28+(1-$M$16)*C28 -> 1002.2398 | E28: =D28-D29 -> 6.2125691 | F28: =-E28 -> -6.2125691 | H28: 22 | I28: =COUNTIF($F:$F,">"&H28)/COUNT(F:F) -> 0.018475751
A29: 44075 | B29: 134.18 | C29: 3499.12 | D29: =$M$16*B29+(1-$M$16)*C29 -> 996.02721 | E29: =D29-D30 -> 16.158522 | F29: =-E29 -> -16.158522 | H29: 23 | I29: =COUNTIF($F:$F,">"&H29)/COUNT(F:F) -> 0.016166282
... A32: 44070 | B32: 125.01 | C32: 3400 | D32: =$M$16*B32+(1-$M$16)*C32 -> 963.81871 | E32: =D32-D33 -> -11.843966 | F32: =-E32 -> 11.843966 | H32: 26 | I32: =COUNTIF($F:$F,">"&H32)/COUNT(F:F) -> 0.013856813
A33: 44069 | B33: 126.5225 | C33: 3441.85 | D33: =$M$16*B33+(1-$M$16)*C33 -> 975.66268 | E33: =D33-D34 -> 25.686862 | F33: =-E33 -> -25.686862 | H33: 27 | I33: =COUNTIF($F:$F,">"&H33)/COUNT(F:F) -> 0.012317167 | J33: Numero di numeri più grandi
A34: 44068 | B34: 124.825 | C34: 3346.49 | D34: =$M$16*B34+(1-$M$16)*C34 -> 949.97582 | E34: =D34-D35 -> 9.2285311 | F34: =-E34 -> -9.2285311 | H34: 28 | I34: =COUNTIF($F:$F,">"&H34)/COUNT(F:F) -> 0.0092378753 | J34: =COUNTIF($F:$F,">"&H34) -> 12 | K34: =J34-J35 -> 2 | L34: =K34/COUNT(F:F) -> 0.0015396459 | M34: =L34*H34 -> 0.043110085
A35: 44067 | B35: 125.8575 | C35: 3307.46 | D35: =$M$16*B35+(1-$M$16)*C35 -> 940.74729 | E35: =D35-D36 -> 6.9308089 | F35: =-E35 -> -6.9308089 | H35: 29 | I35: =COUNTIF($F:$F,">"&H35)/COUNT(F:F) -> 0.0076982294 | J35: =COUNTIF($F:$F,">"&H35) -> 10 | K35: =J35-J36 -> 1 | L35: =K35/COUNT(F:F) -> 0.00076982294 | M35: =L35*H35 -> 0.022324865
A36: 44064 | B36: 124.37 | C36: 3284.72 | D36: =$M$16*B36+(1-$M$16)*C36 -> 933.81648 | E36: =D36-D37 -> 1.293926 | F36: =-E36 -> -1.293926 | H36: 30 | I36: =COUNTIF($F:$F,">"&H36)/COUNT(F:F) -> 0.0069284065 | J36: =COUNTIF($F:$F,">"&H36) -> 9 | K36: =J36-J37 -> 0 | L36: =K36/COUNT(F:F) -> 0 | M36: =L36*H36 -> 0
A37: 44063 | B37: 118.275 | C37: 3297.37 | D37: =$M$16*B37+(1-$M$16)*C37 -> 932.52255 | E37: =D37-D38 -> 11.35837 | F37: =-E37 -> -11.35837 | H37: 31 | I37: =COUNTIF($F:$F,">"&H37)/COUNT(F:F) -> 0.0069284065 | J37: =COUNTIF($F:$F,">"&H37) -> 9 | K37: =J37-J38 -> 2 | L37: =K37/COUNT(F:F) -> 0.0015396459 | M37: =L37*H37 -> 0.047729022
A38: 44062 | B38: 115.7075 | C38: 3260.48 | D38: =$M$16*B38+(1-$M$16)*C38 -> 921.16418 | E38: =D38-D39 -> -13.21323 | F38: =-E38 -> 13.21323 | H38: 32 | I38: =COUNTIF($F:$F,">"&H38)/COUNT(F:F) -> 0.0053887606 | J38: =COUNTIF($F:$F,">"&H38) -> 7 | K38: =J38-J39 -> 1 | L38: =K38/COUNT(F:F) -> 0.00076982294 | M38: =L38*H38 -> 0.024634334
A39: 44061 | B39: 115.5625 | C39: 3312.49 | D39: =$M$16*B39+(1-$M$16)*C39 -> 934.37741 | E39: =D39-D40 -> 34.027216 | F39: =-E39 -> -34.027216 | H39: 33 | I39: =COUNTIF($F:$F,">"&H39)/COUNT(F:F) -> 0.0046189376 | J39: =COUNTIF($F:$F,">"&H39) -> 6 | K39: =J39-J40 -> 0 | L39: =K39/COUNT(F:F) -> 0 | M39: =L39*H39 -> 0
A40: 44060 | B40: 114.6075 | C40: 3182.41 | D40: =$M$16*B40+(1-$M$16)*C40 -> 900.3502 | E40: =D40-D41 -> 8.5849964 | F40: =-E40 -> -8.5849964 | H40: 34 | I40: =COUNTIF($F:$F,">"&H40)/COUNT(F:F) -> 0.0046189376 | J40: =COUNTIF($F:$F,">"&H40) -> 6 | K40: =J40-J41 -> 0 | L40: =K40/COUNT(F:F) -> 0 | M40: =L40*H40 -> 0
A41: 44057 | B41: 114.9075 | C41: 3148.02 | D41: =$M$16*B41+(1-$M$16)*C41 -> 891.7652 | E41: =D41-D42 -> -3.4058797 | F41: =-E41 -> 3.4058797 | H41: 35 | I41: =COUNTIF($F:$F,">"&H41)/COUNT(F:F) -> 0.0046189376 | J41: =COUNTIF($F:$F,">"&H41) -> 6 | K41: =J41-J42 -> 0 | L41: =K41/COUNT(F:F) -> 0 | M41: =L41*H41 -> 0
A42: 44056 | B42: 115.01 | C42: 3161.02 | D42: =$M$16*B42+(1-$M$16)*C42 -> 895.17108 | E42: =D42-D43 -> 1.1752756 | F42: =-E42 -> -1.1752756 | H42: 36 | I42: =COUNTIF($F:$F,">"&H42)/COUNT(F:F) -> 0.0046189376 | J42: =COUNTIF($F:$F,">"&H42) -> 6 | K42: =J42-J43 -> 2 | L42: =K42/COUNT(F:F) -> 0.0015396459 | M42: =L42*H42 -> 0.055427252
...

Sheet Punto 3
A1: =_xll.Thomson.Reuters.AFOSpreadsheetFormulas.DSGRID("@AAPL,@AMZN,@FB"," ","-5Y","","D","RowHeader=true;ColHeader=true;Heading=true;LatestFirstValue=true;DispSeriesDescription=false;YearlyTSFormat=false;QuarterlyTSFormat=false","") -> #NAME? | B1: 42283
A2: End | B2: 44110
A3: Frequency | B3: D
A4: Name | B4: APPLE | C4: ='Historical Simulation'!D4 -> FACEBOOK CLASS A | D4: Portfolio Value [a,1-a] | E4: GAIN | F4: LOSS
A5: 44110 | B5: 113.16 | C5: ='Historical Simulation'!D5 -> 258.6599 | D5: =$M$16*B5+(1-$M$16)*C5 -> 1081.0308 | E5: =D5-D6 -> -20.967899 | F5: =-E5 -> 20.967899
A6: 44109 | B6: 116.5 | C6: ='Historical Simulation'!D6 -> 264.6499 | D6: =$M$16*B6+(1-$M$16)*C6 -> 1101.9987 | E6: =D6-D7 -> 11.662006 | F6: =-E6 -> -11.662006 | H6: Probability Loss is greater than
A7: 44106 | B7: 113.02 | C7: ='Historical Simulation'!D7 -> 259.9399 | D7: =$M$16*B7+(1-$M$16)*C7 -> 1090.3367 | E7: =D7-D8 -> -23.193949 | F7: =-E7 -> 23.193949 | H7: 1 | I7: =COUNTIF($F:$F,">"&H7)/COUNT(F:F) -> 0.43110085
A8: 44105 | B8: 116.79 | C8: ='Historical Simulation'!D8 -> 266.6299 | D8: =$M$16*B8+(1-$M$16)*C8 -> 1113.5306 | E8: =D8-D9 -> 25.92514 | F8: =-E8 -> -25.92514 | H8: 2 | I8: =COUNTIF($F:$F,">"&H8)/COUNT(F:F) -> 0.38953041
A9: 44104 | B9: 115.81 | C9: ='Historical Simulation'!D9 -> 261.8999 | D9: =$M$16*B9+(1-$M$16)*C9 -> 1087.6055 | E9: =D9-D10 -> -8.9904455 | F9: =-E9 -> 8.9904455 | H9: 3 | I9: =COUNTIF($F:$F,">"&H9)/COUNT(F:F) -> 0.35334873
A10: 44103 | B10: 114.09 | C10: ='Historical Simulation'!D10 -> 261.79 | D10: =$M$16*B10+(1-$M$16)*C10 -> 1096.5959 | E10: =D10-D11 -> 37.977233 | F10: =-E10 -> -37.977233 | H10: 4 | I10: =COUNTIF($F:$F,">"&H10)/COUNT(F:F) -> 0.32101617 | L10: Rendimento previsto | M10: ='Punto 3'!M16*'Historical Simulation'!AC5+'Punto 3'!N16*'Historical Simulation'!AE5 -> -0.000854324
A11: 44102 | B11: 114.96 | C11: ='Historical Simulation'!D11 -> 256.8201 | D11: =$M$16*B11+(1-$M$16)*C11 -> 1058.6187 | E11: =D11-D12 -> -1.8427202 | F11: =-E11 -> 1.8427202 | H11: 5 | I11: =COUNTIF($F:$F,">"&H11)/COUNT(F:F) -> 0.30331024
A12: 44099 | B12: 112.28 | C12: ='Historical Simulation'!D12 -> 254.82 | D12: =$M$16*B12+(1-$M$16)*C12 -> 1060.4614 | E12: =D12-D13 -> 12.242006 | F12: =-E12 -> -12.242006 | H12: 6 | I12: =COUNTIF($F:$F,">"&H12)/COUNT(F:F) -> 0.27251732
A13: 44098 | B13: 108.22 | C13: ='Historical Simulation'!D13 -> 249.53 | D13: =$M$16*B13+(1-$M$16)*C13 -> 1048.2194 | E13: =D13-D14 -> -2.8247021 | F13: =-E13 -> 2.8247021 | H13: 7 | I13: =COUNTIF($F:$F,">"&H13)/COUNT(F:F) -> 0.25096228
A14: 44097 | B14: 107.12 | C14: ='Historical Simulation'!D14 -> 249.02 | D14: =$M$16*B14+(1-$M$16)*C14 -> 1051.0441 | E14: =D14-D15 -> -11.608119 | F14: =-E14 -> 11.608119 | H14: 8 | I14: =COUNTIF($F:$F,">"&H14)/COUNT(F:F) -> 0.22632794
A15: 44096 | B15: 111.81 | C15: ='Historical Simulation'!D15 -> 254.75 | D15: =$M$16*B15+(1-$M$16)*C15 -> 1062.6522 | E15: =D15-D16 -> 34.125422 | F15: =-E15 -> -34.125422 | H15: 9 | I15: =COUNTIF($F:$F,">"&H15)/COUNT(F:F) -> 0.20785219
A16: 44095 | B16: 110.08 | C16: ='Historical Simulation'!D16 -> 248.15 | D16: =$M$16*B16+(1-$M$16)*C16 -> 1028.5268 | E16: =D16-D17 -> -47.448525 | F16: =-E16 -> 47.448525 | H16: 10 | I16: =COUNTIF($F:$F,">"&H16)/COUNT(F:F) -> 0.18937644 | L16: a | M16: -5.6520374 | N16: =1-M16 -> 6.6520374
A17: 44092 | B17: 106.84 | C17: ='Historical Simulation'!D17 -> 252.53 | D17: =$M$16*B17+(1-$M$16)*C17 -> 1075.9753 | E17: =D17-D18 -> 4.5489653 | F17: =-E17 -> -4.5489653 | H17: 11 | I17: =COUNTIF($F:$F,">"&H17)/COUNT(F:F) -> 0.1778291 | L17: VaR 95% | M17: 28
A18: 44091 | B18: 110.34 | C18: ='Historical Simulation'!D18 -> 254.82 | D18: =$M$16*B18+(1-$M$16)*C18 -> 1071.4264 | E18: =D18-D19 -> -47.755579 | F18: =-E18 -> 47.755579 | H18: 12 | I18: =COUNTIF($F:$F,">"&H18)/COUNT(F:F) -> 0.16089299
A19: 44090 | B19: 112.13 | C19: ='Historical Simulation'!D19 -> 263.52 | D19: =$M$16*B19+(1-$M$16)*C19 -> 1119.1819 | E19: =D19-D20 -> -39.92902 | F19: =-E19 -> 39.92902 | H19: 13 | I19: =COUNTIF($F:$F,">"&H19)/COUNT(F:F) -> 0.14934565
A20: 44089 | B20: 115.54 | C20: ='Historical Simulation'!D20 -> 272.4199 | D20: =$M$16*B20+(1-$M$16)*C20 -> 1159.111 | E20: =D20-D21 -> 40.662648 | F20: =-E20 -> -40.662648 | H20: 14 | I20: =COUNTIF($F:$F,">"&H20)/COUNT(F:F) -> 0.14472671
A21: 44088 | B21: 115.355 | C21: ='Historical Simulation'!D21 -> 266.1499 | D21: =$M$16*B21+(1-$M$16)*C21 -> 1118.4483 | E21: =D21-D22 -> -22.023853 | F21: =-E21 -> 22.023853 | H21: 15 | I21: =COUNTIF($F:$F,">"&H21)/COUNT(F:F) -> 0.13471901
A22: 44085 | B22: 112 | C22: ='Historical Simulation'!D22 -> 266.6101 | D22: =$M$16*B22+(1-$M$16)*C22 -> 1140.4722 | E22: =D22-D23 -> -1.4234796 | F22: =-E22 -> 1.4234796 | H22: 16 | I22: =COUNTIF($F:$F,">"&H22)/COUNT(F:F) -> 0.12548114
A23: 44084 | B23: 113.49 | C23: ='Historical Simulation'!D23 -> 268.0901 | D23: =$M$16*B23+(1-$M$16)*C23 -> 1141.8957 | E23: =D23-D24 -> -15.803002 | F23: =-E23 -> 15.803002 | H23: 17 | I23: =COUNTIF($F:$F,">"&H23)/COUNT(F:F) -> 0.11316397
A24: 44083 | B24: 117.32 | C24: ='Historical Simulation'!D24 -> 273.72 | D24: =$M$16*B24+(1-$M$16)*C24 -> 1157.6987 | E24: =D24-D25 -> -8.4042874 | F24: =-E24 -> 8.4042874 | H24: 18 | I24: =COUNTIF($F:$F,">"&H24)/COUNT(F:F) -> 0.10700539
A25: 44082 | B25: 112.82 | C25: ='Historical Simulation'!D25 -> 271.1599 | D25: =$M$16*B25+(1-$M$16)*C25 -> 1166.1029 | E25: =D25-D26 -> -30.957154 | F25: =-E25 -> 30.957154 | H25: 19 | I25: =COUNTIF($F:$F,">"&H25)/COUNT(F:F) -> 0.10084681
A26: 44078 | B26: 120.96 | C26: ='Historical Simulation'!D26 -> 282.73 | D26: =$M$16*B26+(1-$M$16)*C26 -> 1197.0601 | E26: =D26-D27 -> -56.263422 | F26: =-E26 -> 56.263422 | H26: 20 | I26: =COUNTIF($F:$F,">"&H26)/COUNT(F:F) -> 0.095458045
A27: 44077 | B27: 120.88 | C27: ='Historical Simulation'!D27 -> 291.1201 | D27: =$M$16*B27+(1-$M$16)*C27 -> 1253.3235 | E27: =D27-D28 -> -16.240087 | F27: =-E27 -> 16.240087 | H27: 21 | I27: =COUNTIF($F:$F,">"&H27)/COUNT(F:F) -> 0.088529638
A28: 44076 | B28: 131.4 | C28: ='Historical Simulation'!D28 -> 302.5 | D28: =$M$16*B28+(1-$M$16)*C28 -> 1269.5636 | E28: =D28-D29 -> 62.676713 | F28: =-E28 -> -62.676713 | H28: 22 | I28: =COUNTIF($F:$F,">"&H28)/COUNT(F:F) -> 0.085450346
A29: 44075 | B29: 134.18 | C29: ='Historical Simulation'!D29 -> 295.4399 | D29: =$M$16*B29+(1-$M$16)*C29 -> 1206.8869 | E29: =D29-D30 -> -14.151574 | F29: =-E29 -> 14.151574 | H29: 23 | I29: =COUNTIF($F:$F,">"&H29)/COUNT(F:F) -> 0.072363356
... A32: 44070 | B32: 125.01 | C32: ='Historical Simulation'!D32 -> 293.22 | D32: =$M$16*B32+(1-$M$16)*C32 -> 1243.9492 | E32: =D32-D33 -> -62.560908 | F32: =-E32 -> 62.560908 | H32: 26 | I32: =COUNTIF($F:$F,">"&H32)/COUNT(F:F) -> 0.057736721
A33: 44069 | B33: 126.5225 | C33: ='Historical Simulation'!D33 -> 303.9099 | D33: =$M$16*B33+(1-$M$16)*C33 -> 1306.5101 | E33: =D33-D34 -> 143.99988 | F33: =-E33 -> -143.99988 | H33: 27 | I33: =COUNTIF($F:$F,">"&H33)/COUNT(F:F) -> 0.05234796 | J33: Numero di numeri più grandi
A34: 44068 | B34: 124.825 | C34: ='Historical Simulation'!D34 -> 280.8201 | D34: =$M$16*B34+(1-$M$16)*C34 -> 1162.5102 | E34: =D34-D35 -> 68.565772 | F34: =-E34 -> -68.565772 | H34: 28 | I34: =COUNTIF($F:$F,">"&H34)/COUNT(F:F) -> 0.049268668 | J34: =COUNTIF($F:$F,">"&H34) -> 64 | K34: =J34-J35 -> 4 | L34: =K34/COUNT(F:F) -> 0.0030792918 | M34: =L34*H34 -> 0.086220169
A35: 44067 | B35: 125.8575 | C35: ='Historical Simulation'!D35 -> 271.3899 | D35: =$M$16*B35+(1-$M$16)*C35 -> 1093.9445 | E35: =D35-D36 -> 20.727853 | F35: =-E35 -> -20.727853 | H35: 29 | I35: =COUNTIF($F:$F,">"&H35)/COUNT(F:F) -> 0.046189376 | J35: =COUNTIF($F:$F,">"&H35) -> 60 | K35: =J35-J36 -> 5 | L35: =K35/COUNT(F:F) -> 0.0038491147 | M35: =L35*H35 -> 0.11162433
A36: 44064 | B36: 124.37 | C36: ='Historical Simulation'!D36 -> 267.01 | D36: =$M$16*B36+(1-$M$16)*C36 -> 1073.2166 | E36: =D36-D37 -> -47.753243 | F36: =-E36 -> 47.753243 | H36: 30 | I36: =COUNTIF($F:$F,">"&H36)/COUNT(F:F) -> 0.042340262 | J36: =COUNTIF($F:$F,">"&H36) -> 55 | K36: =J36-J37 -> 4 | L36: =K36/COUNT(F:F) -> 0.0030792918 | M36: =L36*H36 -> 0.092378753
A37: 44063 | B37: 118.275 | C37: ='Historical Simulation'!D37 -> 269.01 | D37: =$M$16*B37+(1-$M$16)*C37 -> 1120.9699 | E37: =D37-D38 -> 28.193809 | F37: =-E37 -> -28.193809 | H37: 31 | I37: =COUNTIF($F:$F,">"&H37)/COUNT(F:F) -> 0.03926097 | J37: =COUNTIF($F:$F,">"&H37) -> 51 | K37: =J37-J38 -> 6 | L37: =K37/COUNT(F:F) -> 0.0046189376 | M37: =L37*H37 -> 0.14318707
A38: 44062 | B38: 115.7075 | C38: ='Historical Simulation'!D38 -> 262.5901 | D38: =$M$16*B38+(1-$M$16)*C38 -> 1092.7761 | E38: =D38-D39 -> 0.84346393 | F38: =-E38 -> -0.84346393 | H38: 32 | I38: =COUNTIF($F:$F,">"&H38)/COUNT(F:F) -> 0.034642032 | J38: =COUNTIF($F:$F,">"&H38) -> 45 | K38: =J38-J39 -> 2 | L38: =K38/COUNT(F:F) -> 0.0015396459 | M38: =L38*H38 -> 0.049268668
A39: 44061 | B39: 115.5625 | C39: ='Historical Simulation'!D39 -> 262.3401 | D39: =$M$16*B39+(1-$M$16)*C39 -> 1091.9326 | E39: =D39-D40 -> 2.4530388 | F39: =-E39 -> -2.4530388 | H39: 33 | I39: =COUNTIF($F:$F,">"&H39)/COUNT(F:F) -> 0.033102386 | J39: =COUNTIF($F:$F,">"&H39) -> 43 | K39: =J39-J40 -> 1 | L39: =K39/COUNT(F:F) -> 0.00076982294 | M39: =L39*H39 -> 0.025404157
A40: 44060 | B40: 114.6075 | C40: ='Historical Simulation'!D40 -> 261.1599 | D40: =$M$16*B40+(1-$M$16)*C40 -> 1089.4795 | E40: =D40-D41 -> 1.162783 | F40: =-E40 -> -1.162783 | H40: 34 | I40: =COUNTIF($F:$F,">"&H40)/COUNT(F:F) -> 0.032332564 | J40: =COUNTIF($F:$F,">"&H40) -> 42 | K40: =J40-J41 -> 0 | L40: =K40/COUNT(F:F) -> 0 | M40: =L40*H40 -> 0
A41: 44057 | B41: 114.9075 | C41: ='Historical Simulation'!D41 -> 261.24 | D41: =$M$16*B41+(1-$M$16)*C41 -> 1088.3168 | E41: =D41-D42 -> 0.18021159 | F41: =-E41 -> -0.18021159 | H41: 35 | I41: =COUNTIF($F:$F,">"&H41)/COUNT(F:F) -> 0.032332564 | J41: =COUNTIF($F:$F,">"&H41) -> 42 | K41: =J41-J42 -> 1 | L41: =K41/COUNT(F:F) -> 0.00076982294 | M41: =L41*H41 -> 0.026943803
A42: 44056 | B42: 115.01 | C42: ='Historical Simulation'!D42 -> 261.3 | D42: =$M$16*B42+(1-$M$16)*C42 -> 1088.1366 | E42: =D42-D43 -> -1.9240369 | F42: =-E42 -> 1.9240369 | H42: 36 | I42: =COUNTIF($F:$F,">"&H42)/COUNT(F:F) -> 0.031562741 | J42: =COUNTIF($F:$F,">"&H42) -> 41 | K42: =J42-J43 -> 2 | L42: =K42/COUNT(F:F) -> 0.0015396459 | M42: =L42*H42 -> 0.055427252
...

Sheet Punto 4
A1: =_xll.Thomson.Reuters.AFOSpreadsheetFormulas.DSGRID("@AAPL,@AMZN,@FB"," ","-5Y","","D","RowHeader=true;ColHeader=true;Heading=true;LatestFirstValue=true;DispSeriesDescription=false;YearlyTSFormat=false;QuarterlyTSFormat=false","") -> #NAME? | B1: 42283
A2: End | B2: 44110
A3: Frequency | B3: D
A4: Name | B4: APPLE | C4: ='Historical Simulation'!D4 -> FACEBOOK CLASS A | D4: Portfolio Value [a,1-a] | E4: GAIN | F4: LOSS
A5: 44110 | B5: 113.16 | C5: ='Historical Simulation'!D5 -> 258.6599 | D5: =$M$16*B5+(1-$M$16)*C5 -> 583.21728 | E5: =D5-D6 -> -11.901187 | F5: =-E5 -> 11.901187
A6: 44109 | B6: 116.5 | C6: ='Historical Simulation'!D6 -> 264.6499 | D6: =$M$16*B6+(1-$M$16)*C6 -> 595.11846 | E6: =D6-D7 -> 7.4536828 | F6: =-E6 -> -7.4536828 | H6: Probability Loss is greater than
A7: 44106 | B7: 113.02 | C7: ='Historical Simulation'!D7 -> 259.9399 | D7: =$M$16*B7+(1-$M$16)*C7 -> 587.66478 | E7: =D7-D8 -> -13.203458 | F7: =-E7 -> 13.203458 | H7: 1 | I7: =COUNTIF($F:$F,">"&H7)/COUNT(F:F) -> 0.38799076 | L7: Rendimento previsto | M7: =M16*'Historical Simulation'!AC5+'Punto 4'!N16*'Historical Simulation'!AE5 -> 0.00014051768
A8: 44105 | B8: 116.79 | C8: ='Historical Simulation'!D8 -> 266.6299 | D8: =$M$16*B8+(1-$M$16)*C8 -> 600.86824 | E8: =D8-D9 -> 13.094887 | F8: =-E8 -> -13.094887 | H8: 2 | I8: =COUNTIF($F:$F,">"&H8)/COUNT(F:F) -> 0.32024634
A9: 44104 | B9: 115.81 | C9: ='Historical Simulation'!D9 -> 261.8999 | D9: =$M$16*B9+(1-$M$16)*C9 -> 587.77335 | E9: =D9-D10 -> -3.4816477 | F9: =-E9 -> 3.4816477 | H9: 3 | I9: =COUNTIF($F:$F,">"&H9)/COUNT(F:F) -> 0.26789838
A10: 44103 | B10: 114.09 | C10: ='Historical Simulation'!D10 -> 261.79 | D10: =$M$16*B10+(1-$M$16)*C10 -> 591.255 | E10: =D10-D11 -> 17.996594 | F10: =-E10 -> -17.996594 | H10: 4 | I10: =COUNTIF($F:$F,">"&H10)/COUNT(F:F) -> 0.22324865
A11: 44102 | B11: 114.96 | C11: ='Historical Simulation'!D11 -> 256.8201 | D11: =$M$16*B11+(1-$M$16)*C11 -> 573.25841 | E11: =D11-D12 -> 0.4834903 | F11: =-E11 -> -0.4834903 | H11: 5 | I11: =COUNTIF($F:$F,">"&H11)/COUNT(F:F) -> 0.18552733
A12: 44099 | B12: 112.28 | C12: ='Historical Simulation'!D12 -> 254.82 | D12: =$M$16*B12+(1-$M$16)*C12 -> 572.77492 | E12: =D12-D13 -> 8.0336828 | F12: =-E12 -> -8.0336828 | H12: 6 | I12: =COUNTIF($F:$F,">"&H12)/COUNT(F:F) -> 0.15550423
A13: 44098 | B13: 108.22 | C13: ='Historical Simulation'!D13 -> 249.53 | D13: =$M$16*B13+(1-$M$16)*C13 -> 564.74123 | E13: =D13-D14 -> -0.80607549 | F13: =-E13 -> 0.80607549 | H13: 7 | I13: =COUNTIF($F:$F,">"&H13)/COUNT(F:F) -> 0.14241724
A14: 44097 | B14: 107.12 | C14: ='Historical Simulation'!D14 -> 249.02 | D14: =$M$16*B14+(1-$M$16)*C14 -> 565.54731 | E14: =D14-D15 -> -8.0498619 | F14: =-E14 -> 8.0498619 | H14: 8 | I14: =COUNTIF($F:$F,">"&H14)/COUNT(F:F) -> 0.12240185
A15: 44096 | B15: 111.81 | C15: ='Historical Simulation'!D15 -> 254.75 | D15: =$M$16*B15+(1-$M$16)*C15 -> 573.59717 | E15: =D15-D16 -> 17.463199 | F15: =-E15 -> -17.463199 | H15: 9 | I15: =COUNTIF($F:$F,">"&H15)/COUNT(F:F) -> 0.10700539
A16: 44095 | B16: 110.08 | C16: ='Historical Simulation'!D16 -> 248.15 | D16: =$M$16*B16+(1-$M$16)*C16 -> 556.13397 | E16: =D16-D17 -> -21.37745 | F16: =-E16 -> 21.37745 | H16: 10 | I16: =COUNTIF($F:$F,">"&H16)/COUNT(F:F) -> 0.092378753 | L16: a | M16: -2.2306364 | N16: =1-M16 -> 3.2306364
A17: 44092 | B17: 106.84 | C17: ='Historical Simulation'!D17 -> 252.53 | D17: =$M$16*B17+(1-$M$16)*C17 -> 577.51142 | E17: =D17-D18 -> 0.40907007 | F17: =-E17 -> -0.40907007 | H17: 11 | I17: =COUNTIF($F:$F,">"&H17)/COUNT(F:F) -> 0.082371055 | L17: VaR 99% | M17: 28
A18: 44091 | B18: 110.34 | C18: ='Historical Simulation'!D18 -> 254.82 | D18: =$M$16*B18+(1-$M$16)*C18 -> 577.10235 | E18: =D18-D19 -> -24.113698 | F18: =-E18 -> 24.113698 | H18: 12 | I18: =COUNTIF($F:$F,">"&H18)/COUNT(F:F) -> 0.063895304
A19: 44090 | B19: 112.13 | C19: ='Historical Simulation'!D19 -> 263.52 | D19: =$M$16*B19+(1-$M$16)*C19 -> 601.21605 | E19: =D19-D20 -> -21.145871 | F19: =-E19 -> 21.145871 | H19: 13 | I19: =COUNTIF($F:$F,">"&H19)/COUNT(F:F) -> 0.059276366
A20: 44089 | B20: 115.54 | C20: ='Historical Simulation'!D20 -> 272.4199 | D20: =$M$16*B20+(1-$M$16)*C20 -> 622.36192 | E20: =D20-D21 -> 19.843423 | F20: =-E20 -> -19.843423 | H20: 14 | I20: =COUNTIF($F:$F,">"&H20)/COUNT(F:F) -> 0.050038491
A21: 44088 | B21: 115.355 | C21: ='Historical Simulation'!D21 -> 266.1499 | D21: =$M$16*B21+(1-$M$16)*C21 -> 602.5185 | E21: =D21-D22 -> -8.9705241 | F21: =-E21 -> 8.9705241 | H21: 15 | I21: =COUNTIF($F:$F,">"&H21)/COUNT(F:F) -> 0.043879908
A22: 44085 | B22: 112 | C22: ='Historical Simulation'!D22 -> 266.6101 | D22: =$M$16*B22+(1-$M$16)*C22 -> 611.48902 | E22: =D22-D23 -> -1.4576936 | F22: =-E22 -> 1.4576936 | H22: 16 | I22: =COUNTIF($F:$F,">"&H22)/COUNT(F:F) -> 0.036181678
A23: 44084 | B23: 113.49 | C23: ='Historical Simulation'!D23 -> 268.0901 | D23: =$M$16*B23+(1-$M$16)*C23 -> 612.94671 | E23: =D23-D24 -> -9.6448225 | F23: =-E23 -> 9.6448225 | H23: 17 | I23: =COUNTIF($F:$F,">"&H23)/COUNT(F:F) -> 0.033872209
A24: 44083 | B24: 117.32 | C24: ='Historical Simulation'!D24 -> 273.72 | D24: =$M$16*B24+(1-$M$16)*C24 -> 622.59154 | E24: =D24-D25 -> -1.7671116 | F24: =-E24 -> 1.7671116 | H24: 18 | I24: =COUNTIF($F:$F,">"&H24)/COUNT(F:F) -> 0.030792918
A25: 44082 | B25: 112.82 | C25: ='Historical Simulation'!D25 -> 271.1599 | D25: =$M$16*B25+(1-$M$16)*C25 -> 624.35865 | E25: =D25-D26 -> -19.221406 | F25: =-E25 -> 19.221406 | H25: 19 | I25: =COUNTIF($F:$F,">"&H25)/COUNT(F:F) -> 0.027713626
A26: 44078 | B26: 120.96 | C26: ='Historical Simulation'!D26 -> 282.73 | D26: =$M$16*B26+(1-$M$16)*C26 -> 643.58005 | E26: =D26-D27 -> -27.283814 | F26: =-E26 -> 27.283814 | H26: 20 | I26: =COUNTIF($F:$F,">"&H26)/COUNT(F:F) -> 0.025404157
A27: 44077 | B27: 120.88 | C27: ='Historical Simulation'!D27 -> 291.1201 | D27: =$M$16*B27+(1-$M$16)*C27 -> 670.86387 | E27: =D27-D28 -> -13.298024 | F27: =-E27 -> 13.298024 | H27: 21 | I27: =COUNTIF($F:$F,">"&H27)/COUNT(F:F) -> 0.023864511
A28: 44076 | B28: 131.4 | C28: ='Historical Simulation'!D28 -> 302.5 | D28: =$M$16*B28+(1-$M$16)*C28 -> 684.16189 | E28: =D28-D29 -> 29.009785 | F28: =-E28 -> -29.009785 | H28: 22 | I28: =COUNTIF($F:$F,">"&H28)/COUNT(F:F) -> 0.020015396
A29: 44075 | B29: 134.18 | C29: ='Historical Simulation'!D29 -> 295.4399 | D29: =$M$16*B29+(1-$M$16)*C29 -> 655.15211 | E29: =D29-D30 -> -4.2291687 | F29: =-E29 -> 4.2291687 | H29: 23 | I29: =COUNTIF($F:$F,">"&H29)/COUNT(F:F) -> 0.016166282
... A32: 44070 | B32: 125.01 | C32: ='Historical Simulation'!D32 -> 293.22 | D32: =$M$16*B32+(1-$M$16)*C32 -> 668.43535 | E32: =D32-D33 -> -31.161343 | F32: =-E32 -> 31.161343 | H32: 26 | I32: =COUNTIF($F:$F,">"&H32)/COUNT(F:F) -> 0.010777521
A33: 44069 | B33: 126.5225 | C33: ='Historical Simulation'!D33 -> 303.9099 | D33: =$M$16*B33+(1-$M$16)*C33 -> 699.5967 | E33: =D33-D34 -> 70.808244 | F33: =-E33 -> -70.808244 | H33: 27 | I33: =COUNTIF($F:$F,">"&H33)/COUNT(F:F) -> 0.010007698 | J33: Numero di numeri più grandi
A34: 44068 | B34: 124.825 | C34: ='Historical Simulation'!D34 -> 280.8201 | D34: =$M$16*B34+(1-$M$16)*C34 -> 628.78845 | E34: =D34-D35 -> 32.76868 | F34: =-E34 -> -32.76868 | H34: 28 | I34: =COUNTIF($F:$F,">"&H34)/COUNT(F:F) -> 0.0092378753 | J34: =COUNTIF($F:$F,">"&H34) -> 12 | K34: =J34-J35 -> 2 | L34: =K34/COUNT(F:F) -> 0.0015396459 | M34: =L34*H34 -> 0.043110085
A35: 44067 | B35: 125.8575 | C35: ='Historical Simulation'!D35 -> 271.3899 | D35: =$M$16*B35+(1-$M$16)*C35 -> 596.01977 | E35: =D35-D36 -> 10.831793 | F35: =-E35 -> -10.831793 | H35: 29 | I35: =COUNTIF($F:$F,">"&H35)/COUNT(F:F) -> 0.0076982294 | J35: =COUNTIF($F:$F,">"&H35) -> 10 | K35: =J35-J36 -> 0 | L35: =K35/COUNT(F:F) -> 0 | M35: =L35*H35 -> 0
A36: 44064 | B36: 124.37 | C36: ='Historical Simulation'!D36 -> 267.01 | D36: =$M$16*B36+(1-$M$16)*C36 -> 585.18798 | E36: =D36-D37 -> -20.057002 | F36: =-E36 -> 20.057002 | H36: 30 | I36: =COUNTIF($F:$F,">"&H36)/COUNT(F:F) -> 0.0076982294 | J36: =COUNTIF($F:$F,">"&H36) -> 10 | K36: =J36-J37 -> 2 | L36: =K36/COUNT(F:F) -> 0.0015396459 | M36: =L36*H36 -> 0.046189376
A37: 44063 | B37: 118.275 | C37: ='Historical Simulation'!D37 -> 269.01 | D37: =$M$16*B37+(1-$M$16)*C37 -> 605.24498 | E37: =D37-D38 -> 15.013204 | F37: =-E37 -> -15.013204 | H37: 31 | I37: =COUNTIF($F:$F,">"&H37)/COUNT(F:F) -> 0.0061585835 | J37: =COUNTIF($F:$F,">"&H37) -> 8 | K37: =J37-J38 -> 1 | L37: =K37/COUNT(F:F) -> 0.00076982294 | M37: =L37*H37 -> 0.023864511
A38: 44062 | B38: 115.7075 | C38: ='Historical Simulation'!D38 -> 262.5901 | D38: =$M$16*B38+(1-$M$16)*C38 -> 590.23178 | E38: =D38-D39 -> 0.48421682 | F38: =-E38 -> -0.48421682 | H38: 32 | I38: =COUNTIF($F:$F,">"&H38)/COUNT(F:F) -> 0.0053887606 | J38: =COUNTIF($F:$F,">"&H38) -> 7 | K38: =J38-J39 -> 0 | L38: =K38/COUNT(F:F) -> 0 | M38: =L38*H38 -> 0
A39: 44061 | B39: 115.5625 | C39: ='Historical Simulation'!D39 -> 262.3401 | D39: =$M$16*B39+(1-$M$16)*C39 -> 589.74756 | E39: =D39-D40 -> 1.6825393 | F39: =-E39 -> -1.6825393 | H39: 33 | I39: =COUNTIF($F:$F,">"&H39)/COUNT(F:F) -> 0.0053887606 | J39: =COUNTIF($F:$F,">"&H39) -> 7 | K39: =J39-J40 -> 0 | L39: =K39/COUNT(F:F) -> 0 | M39: =L39*H39 -> 0
A40: 44060 | B40: 114.6075 | C40: ='Historical Simulation'!D40 -> 261.1599 | D40: =$M$16*B40+(1-$M$16)*C40 -> 588.06502 | E40: =D40-D41 -> 0.41041695 | F40: =-E40 -> -0.41041695 | H40: 34 | I40: =COUNTIF($F:$F,">"&H40)/COUNT(F:F) -> 0.0053887606 | J40: =COUNTIF($F:$F,">"&H40) -> 7 | K40: =J40-J41 -> 0 | L40: =K40/COUNT(F:F) -> 0 | M40: =L40*H40 -> 0
A41: 44057 | B41: 114.9075 | C41: ='Historical Simulation'!D41 -> 261.24 | D41: =$M$16*B41+(1-$M$16)*C41 -> 587.6546 | E41: =D41-D42 -> 0.034802048 | F41: =-E41 -> -0.034802048 | H41: 35 | I41: =COUNTIF($F:$F,">"&H41)/COUNT(F:F) -> 0.0053887606 | J41: =COUNTIF($F:$F,">"&H41) -> 7 | K41: =J41-J42 -> 1 | L41: =K41/COUNT(F:F) -> 0.00076982294 | M41: =L41*H41 -> 0.026943803
A42: 44056 | B42: 115.01 | C42: ='Historical Simulation'!D42 -> 261.3 | D42: =$M$16*B42+(1-$M$16)*C42 -> 587.6198 | E42: =D42-D43 -> 0.094247574 | F42: =-E42 -> -0.094247574 | H42: 36 | I42: =COUNTIF($F:$F,">"&H42)/COUNT(F:F) -> 0.0046189376 | J42: =COUNTIF($F:$F,">"&H42) -> 6 | K42: =J42-J43 -> 0 | L42: =K42/COUNT(F:F) -> 0 | M42: =L42*H42 -> 0
...

Sheet Punto 5
A1: =_xll.Thomson.Reuters.AFOSpreadsheetFormulas.DSGRID("@AAPL,@AMZN,@FB"," ","-5Y","","D","RowHeader=true;ColHeader=true;Heading=true;LatestFirstValue=true;DispSeriesDescription=false;YearlyTSFormat=false;QuarterlyTSFormat=false","") -> #NAME? | B1: 42283
A2: End | B2: 44110
A3: Frequency | B3: D
A4: Name | B4: APPLE | C4: AMAZON.COM | D4: FACEBOOK CLASS A | E4: Rend Apple | F4: Rend Amazon.com | G4: Rend Facebook | J4: =AVERAGE(E5:E1303) -> 0.0010798907 | M4: 1 | P4: Valore di portafoglio | Q4: Gain | R4: Loss
A5: 44110 | B5: 113.16 | C5: 3099.96 | D5: 258.6599 | E5: =LN(B5/B6) -> -0.029088527 | F5: =LN(C5/C6) -> -0.03151157 | G5: =LN(D5/D6) -> -0.022893749 | I5: e= | J5: =AVERAGE(F5:F1303) -> 0.0013489245 | L5: ones | M5: 1 | P5: =B5*$J$13+C5*$J$14+D5*$J$15 -> 1246.7293 | Q5: =P5-P6 -> -39.298451 | R5: =-Q5 -> 39.298451
A6: 44109 | B6: 116.5 | C6: 3199.2 | D6: 264.6499 | E6: =LN(B6/B7) -> 0.030326479 | F6: =LN(C6/C7) -> 0.023466495 | G6: =LN(D6/D7) -> 0.01795737 | J6: =AVERAGE(G5:G1303) -> 0.00078912042 | M6: 1 | P6: =B6*$J$13+C6*$J$14+D6*$J$15 -> 1286.0278 | Q6: =P6-P7 -> 29.840071 | R6: =-Q6 -> -29.840071
A7: 44106 | B7: 113.02 | C7: 3125 | D7: 259.9399 | E7: =LN(B7/B8) -> -0.032812656 | F7: =LN(C7/C8) -> -0.030338304 | G7: =LN(D7/D8) -> -0.025411104 | P7: =B7*$J$13+C7*$J$14+D7*$J$15 -> 1256.1877 | Q7: =P7-P8 -> -38.528778 | R7: =-Q7 -> 38.528778
A8: 44105 | B8: 116.79 | C8: 3221.26 | D8: 266.6299 | E8: =LN(B8/B9) -> 0.0084265331 | F8: =LN(C8/C9) -> 0.02277339 | G8: =LN(D8/D9) -> 0.017899185 | P8: =B8*$J$13+C8*$J$14+D8*$J$15 -> 1294.7165 | Q8: =P8-P9 -> 28.19243 | R8: =-Q8 -> -28.19243 | T8: Probability loss bigger than
A9: 44104 | B9: 115.81 | C9: 3148.73 | D9: 261.8999 | E9: =LN(B9/B10) -> 0.014963307 | F9: =LN(C9/C10) -> 0.0012234633 | G9: =LN(D9/D10) -> 0.00041971404 | I9: Var= | J9: =_xlfn.COVARIANCE.S($E$5:$E$1303,E5:E1303) -> 0.0003428625 | K9: =_xlfn.COVARIANCE.S($E$5:$E$1303,F5:F1303) -> 0.00020102478 | L9: =_xlfn.COVARIANCE.S($E$5:$E$1303,G5:G1303) -> 0.00021213092 | P9: =B9*$J$13+C9*$J$14+D9*$J$15 -> 1266.5241 | Q9: =P9-P10 -> 2.1569767 | R9: =-Q9 -> -2.1569767 | T9: 0 | U9: =COUNTIF($R:$R,">"&T9)/COUNT(R:R) -> 0.42449923
A10: 44103 | B10: 114.09 | C10: 3144.88 | D10: 261.79 | E10: =LN(B10/B11) -> -0.0075966312 | F10: =LN(C10/C11) -> -0.0092326414 | G10: =LN(D10/D11) -> 0.019166816 | J10: =_xlfn.COVARIANCE.S($F$5:$F$1303,E5:E1303) -> 0.00020102478 | K10: =_xlfn.COVARIANCE.S($F$5:$F$1303,F5:F1303) -> 0.00034787892 | L10: =_xlfn.COVARIANCE.S($F$5:$F$1303,G5:G1303) -> 0.00023327103 | P10: =B10*$J$13+C10*$J$14+D10*$J$15 -> 1264.3671 | Q10: =P10-P11 -> -10.046257 | R10: =-Q10 -> 10.046257 | T10: 1 | U10: =COUNTIF($R:$R,">"&T10)/COUNT(R:R) -> 0.36979969
A11: 44102 | B11: 114.96 | C11: 3174.05 | D11: 256.8201 | E11: =LN(B11/B12) -> 0.02358849 | F11: =LN(C11/C12) -> 0.025178466 | G11: =LN(D11/D12) -> 0.0078184262 | J11: =_xlfn.COVARIANCE.S($G$5:$G$1303,E5:E1303) -> 0.00021213092 | K11: =_xlfn.COVARIANCE.S($G$5:$G$1303,F5:F1303) -> 0.00023327103 | L11: =_xlfn.COVARIANCE.S($G$5:$G$1303,G5:G1303) -> 0.00040716688 | P11: =B11*$J$13+C11*$J$14+D11*$J$15 -> 1274.4133 | Q11: =P11-P12 -> 30.662883 | R11: =-Q11 -> -30.662883 | T11: 2 | U11: =COUNTIF($R:$R,">"&T11)/COUNT(R:R) -> 0.298151
A12: 44099 | B12: 112.28 | C12: 3095.13 | D12: 254.82 | E12: =LN(B12/B13) -> 0.036829559 | F12: =LN(C12/C13) -> 0.024642616 | G12: =LN(D12/D13) -> 0.020978265 | P12: =B12*$J$13+C12*$J$14+D12*$J$15 -> 1243.7505 | Q12: =P12-P13 -> 30.626694 | R12: =-Q12 -> -30.626694 | T12: 3 | U12: =COUNTIF($R:$R,">"&T12)/COUNT(R:R) -> 0.24961479
A13: 44098 | B13: 108.22 | C13: 3019.79 | D13: 249.53 | E13: =LN(B13/B14) -> 0.010216491 | F13: =LN(C13/C14) -> 0.0066216716 | G13: =LN(D13/D14) -> 0.0020459339 | I13: wMVP= | J13: {=MMULT(MINVERSE(J9:L11),M4:M6)/(MMULT(MMULT(TRANSPOSE(M4:M6),MINVERSE(J9:L11)),M4:M6))} -> 0.41431856 | P13: =B13*$J$13+C13*$J$14+D13*$J$15 -> 1213.1238 | Q13: =P13-P14 -> 7.9198334 | R13: =-Q13 -> -7.9198334 | T13: 4 | U13: =COUNTIF($R:$R,">"&T13)/COUNT(R:R) -> 0.21186441
A14: 44097 | B14: 107.12 | C14: 2999.86 | D14: 249.02 | E14: =LN(B14/B15) -> -0.042851301 | F14: =LN(C14/C15) -> -0.042144648 | G14: =LN(D14/D15) -> -0.022749458 | J14: 0.36896938 | P14: =B14*$J$13+C14*$J$14+D14*$J$15 -> 1205.2039 | Q14: =P14-P15 -> -50.829931 | R14: =-Q14 -> 50.829931 | T14: 5 | U14: =COUNTIF($R:$R,">"&T14)/COUNT(R:R) -> 0.18104777
A15: 44096 | B15: 111.81 | C15: 3128.99 | D15: 254.75 | E15: =LN(B15/B16) -> 0.015593628 | F15: =LN(C15/C16) -> 0.055362229 | G15: =LN(D15/D16) -> 0.02624927 | J15: 0.21671205 | P15: =B15*$J$13+C15*$J$14+D15*$J$15 -> 1256.0339 | Q15: =P15-P16 -> 64.325791 | R15: =-Q15 -> -64.325791 | T15: 6 | U15: =COUNTIF($R:$R,">"&T15)/COUNT(R:R) -> 0.15793529
A16: 44095 | B16: 110.08 | C16: 2960.47 | D16: 248.15 | E16: =LN(B16/B17) -> 0.029874986 | F16: =LN(C16/C17) -> 0.001879846 | G16: =LN(D16/D17) -> -0.017496652 | P16: =B16*$J$13+C16*$J$14+D16*$J$15 -> 1191.7081 | Q16: =P16-P17 -> 2.4446631 | R16: =-Q16 -> -2.4446631 | T16: 7 | U16: =COUNTIF($R:$R,">"&T16)/COUNT(R:R) -> 0.1394453
A17: 44092 | B17: 106.84 | C17: 2954.91 | D17: 252.53 | E17: =LN(B17/B18) -> -0.03223412 | F17: =LN(C17/C18) -> -0.018049869 | G17: =LN(D17/D18) -> -0.00902736 | P17: =B17*$J$13+C17*$J$14+D17*$J$15 -> 1189.2634 | Q17: =P17-P18 -> -21.804318 | R17: =-Q17 -> 21.804318 | T17: 8 | U17: =COUNTIF($R:$R,">"&T17)/COUNT(R:R) -> 0.12711864
A18: 44091 | B18: 110.34 | C18: 3008.73 | D18: 254.82 | E18: =LN(B18/B19) -> -0.016092405 | F18: =LN(C18/C19) -> -0.022794461 | G18: =LN(D18/D19) -> -0.033571853 | P18: =B18*$J$13+C18*$J$14+D18*$J$15 -> 1211.0677 | Q18: =P18-P19 -> -28.222431 | R18: =-Q18 -> 28.222431 | T18: 9 | U18: =COUNTIF($R:$R,">"&T18)/COUNT(R:R) -> 0.1201849
A19: 44090 | B19: 112.13 | C19: 3078.1 | D19: 263.52 | E19: =LN(B19/B20) -> -0.029957878 | F19: =LN(C19/C20) -> -0.02503407 | G19: =LN(D19/D20) -> -0.03321536 | P19: =B19*$J$13+C19*$J$14+D19*$J$15 -> 1239.2902 | Q19: =P19-P20 -> -32.132223 | R19: =-Q19 -> 32.132223 | T19: 10 | U19: =COUNTIF($R:$R,">"&T19)/COUNT(R:R) -> 0.10785824
A20: 44089 | B20: 115.54 | C20: 3156.13 | D20: 272.4199 | E20: =LN(B20/B21) -> 0.0016024603 | F20: =LN(C20/C21) -> 0.016986876 | G20: =LN(D20/D21) -> 0.023284942 | I20: rendimento previsto | J20: =J13*'Historical Simulation'!AC5+'Punto 5'!J14*'Historical Simulation'!AD5+'Punto 5'!J15*'Historical Simulation'!AE5 -> 0.0011161425 | P20: =B20*$J$13+C20*$J$14+D20*$J$15 -> 1271.4224 | Q20: =P20-P21 -> 21.049846 | R20: =-Q20 -> -21.049846 | T20: 11 | U20: =COUNTIF($R:$R,">"&T20)/COUNT(R:R) -> 0.098613251
A21: 44088 | B21: 115.355 | C21: 3102.97 | D21: 266.1499 | E21: =LN(B21/B22) -> 0.029515459 | F21: =LN(C21/C22) -> -0.0042610115 | G21: =LN(D21/D22) -> -0.0017276076 | P21: =B21*$J$13+C21*$J$14+D21*$J$15 -> 1250.3725 | Q21: =P21-P22 -> -3.5985365 | R21: =-Q21 -> 3.5985365 | T21: 12 | U21: =COUNTIF($R:$R,">"&T21)/COUNT(R:R) -> 0.087827427
A22: 44085 | B22: 112 | C22: 3116.22 | D22: 266.6101 | E22: =LN(B22/B23) -> -0.013215856 | F22: =LN(C22/C23) -> -0.018721549 | G22: =LN(D22/D23) -> -0.0055358265 | P22: =B22*$J$13+C22*$J$14+D22*$J$15 -> 1253.9711 | Q22: =P22-P23 -> -22.666676 | R22: =-Q22 -> 22.666676 | T22: 13 | U22: =COUNTIF($R:$R,">"&T22)/COUNT(R:R) -> 0.082434515
A23: 44084 | B23: 113.49 | C23: 3175.11 | D23: 268.0901 | E23: =LN(B23/B24) -> -0.033190517 | F23: =LN(C23/C24) -> -0.029022541 | G23: =LN(D23/D24) -> -0.020782568 | P23: =B23*$J$13+C23*$J$14+D23*$J$15 -> 1276.6378 | Q23: =P23-P24 -> -37.305545 | R23: =-Q23 -> 37.305545 | T23: 14 | U23: =COUNTIF($R:$R,">"&T23)/COUNT(R:R) -> 0.074730354 | X23: VAR a 1% | Y23: 40
A24: 44083 | B24: 117.32 | C24: 3268.61 | D24: 273.72 | E24: =LN(B24/B25) -> 0.039111616 | F24: =LN(C24/C25) -> 0.03701316 | G24: =LN(D24/D25) -> 0.0093970023 | P24: =B24*$J$13+C24*$J$14+D24*$J$15 -> 1313.9433 | Q24: =P24-P25 -> 46.241732 | R24: =-Q24 -> -46.241732 | T24: 15 | U24: =COUNTIF($R:$R,">"&T24)/COUNT(R:R) -> 0.067026194
A25: 44082 | B25: 112.82 | C25: 3149.84 | D25: 271.1599 | E25: =LN(B25/B26) -> -0.069666284 | F25: =LN(C25/C26) -> -0.044939177 | G25: =LN(D25/D26) -> -0.041783695 | P25: =B25*$J$13+C25*$J$14+D25*$J$15 -> 1267.7016 | Q25: =P25-P26 -> -59.299321 | R25: =-Q25 -> 59.299321 | T25: 16 | U25: =COUNTIF($R:$R,">"&T25)/COUNT(R:R) -> 0.064714946
A26: 44078 | B26: 120.96 | C26: 3294.62 | D26: 282.73 | E26: =LN(B26/B27) -> 0.00066159447 | F26: =LN(C26/C27) -> -0.022028261 | G26: =LN(D26/D27) -> -0.029243518 | P26: =B26*$J$13+C26*$J$14+D26*$J$15 -> 1327.0009 | Q26: =P26-P27 -> -28.860064 | R26: =-Q26 -> 28.860064 | T26: 17 | U26: =COUNTIF($R:$R,">"&T26)/COUNT(R:R) -> 0.060862866
A27: 44077 | B27: 120.88 | C27: 3368 | D27: 291.1201 | E27: =LN(B27/B28) -> -0.083447788 | F27: =LN(C27/C28) -> -0.047389455 | G27: =LN(D27/D28) -> -0.038345381 | P27: =B27*$J$13+C27*$J$14+D27*$J$15 -> 1355.8609 | Q27: =P27-P28 -> -67.132839 | R27: =-Q27 -> 67.132839 | T27: 18 | U27: =COUNTIF($R:$R,">"&T27)/COUNT(R:R) -> 0.05624037
